{
  "version": 8,
  "blockIdVersion": 11,
  "anchorX": 0,
  "anchorY": 0,
  "anchorZ": 0,
  "blocks": [
    {
      "x": -5,
      "y": 0,
      "z": -7,
      "name": "Prototype_Rock_Concrete_Brick"
    },
    {
      "x": -5,
      "y": 1,
      "z": -7,
      "name": "Prototype_Rock_Concrete_Brick"
    },
    {
      "x": -5,
      "y": 2,
      "z": -7,
      "name": "Prototype_Rock_Concrete_Brick"
    },
    {
      "x": -5,
      "y": 3,
      "z": -7,
      "name": "Prototype_Rock_Concrete_Brick"
    },
    {
      "x": -5,
      "y": 4,
      "z": -7,
      "name": "Prototype_Rock_Concrete_Brick"
    },
    {
      "x": -5,
      "y": 5,
      "z": -7,
      "name": "Prototype_Rock_Concrete_Brick"
    },
    {
      "x": -5,
      "y": 0,
      "z": -6,
      "name": "Prototype_Rock_Concrete_Brick"
    },
    {
      "x": -5,
      "y": 1,
      "z": -6,
      "name": "Build_Lightsource_Red"
    },
    {
      "x": -5,
      "y": 2,
      "z": -6,
      "name": "Cloth_Block_Wool_Pink"
    },
    {
      "x": -5,
      "y": 3,
      "z": -6,
      "name": "Cloth_Block_Wool_Orange"
    },
    {
      "x": -5,
      "y": 4,
      "z": -6,
      "name": "Cloth_Block_Wool_Black"
    },
    {
      "x": -5,
      "y": 5,
      "z": -6,
      "name": "Prototype_Rock_Concrete_Brick"
    },
    {
      "x": -5,
      "y": 0,
      "z": -5,
      "name": "Prototype_Rock_Concrete_Brick"
    },
    {
      "x": -5,
      "y": 1,
      "z": -5,
      "name": "Cloth_Block_Wool_White"
    },
    {
      "x": -5,
      "y": 2,
      "z": -5,
      "name": "Cloth_Block_Wool_Blue_Light"
    },
    {
      "x": -5,
      "y": 3,
      "z": -5,
      "name": "Cloth_Block_Wool_Red"
    },
    {
      "x": -5,
      "y": 4,
      "z": -5,
      "name": "Cloth_Block_Wool_Purple"
    },
    {
      "x": -5,
      "y": 5,
      "z": -5,
      "name": "Prototype_Rock_Concrete_Brick"
    },
    {
      "x": -5,
      "y": 0,
      "z": -4,
      "name": "Prototype_Rock_Concrete_Brick"
    },
    {
      "x": -5,
      "y": 1,
      "z": -4,
      "name": "Prototype_Rock_Concrete_Brick"
    },
    {
      "x": -5,
      "y": 2,
      "z": -4,
      "name": "Cloth_Block_Wool_Yellow"
    },
    {
      "x": -5,
      "y": 3,
      "z": -4,
      "name": "Cloth_Block_Wool_Gray_Light"
    },
    {
      "x": -5,
      "y": 4,
      "z": -4,
      "name": "Cloth_Block_Wool_Blue"
    },
    {
      "x": -5,
      "y": 5,
      "z": -4,
      "name": "Prototype_Rock_Concrete_Brick"
    },
    {
      "x": -5,
      "y": 0,
      "z": -3,
      "name": "Prototype_Rock_Concrete_Brick"
    },
    {
      "x": -5,
      "y": 1,
      "z": -3,
      "name": "Prototype_Rock_Concrete_Brick"
    },
    {
      "x": -5,
      "y": 2,
      "z": -3,
      "name": "Prototype_Rock_Concrete_Brick"
    },
    {
      "x": -5,
      "y": 3,
      "z": -3,
      "name": "Prototype_Rock_Concrete_Brick"
    },
    {
      "x": -5,
      "y": 4,
      "z": -3,
      "name": "Prototype_Rock_Concrete_Brick"
    },
    {
      "x": -5,
      "y": 5,
      "z": -3,
      "name": "Prototype_Rock_Concrete_Brick"
    },
    {
      "x": -5,
      "y": 0,
      "z": -2,
      "name": "Prototype_Rock_Concrete_Brick"
    },
    {
      "x": -5,
      "y": 1,
      "z": -2,
      "name": "Prototype_Rock_Concrete_Brick"
    },
    {
      "x": -5,
      "y": 2,
      "z": -2,
      "name": "Prototype_Rock_Concrete_Brick"
    },
    {
      "x": -5,
      "y": 3,
      "z": -2,
      "name": "Prototype_Rock_Concrete_Brick"
    },
    {
      "x": -5,
      "y": 4,
      "z": -2,
      "name": "Prototype_Rock_Concrete_Brick"
    },
    {
      "x": -5,
      "y": 5,
      "z": -2,
      "name": "Prototype_Rock_Concrete_Brick"
    },
    {
      "x": -4,
      "y": 0,
      "z": -7,
      "name": "Prototype_Rock_Concrete_Brick"
    },
    {
      "x": -4,
      "y": 0,
      "z": -6,
      "name": "Prototype_Rock_Concrete_Brick"
    },
    {
      "x": -4,
      "y": 0,
      "z": -5,
      "name": "Prototype_Rock_Concrete_Brick"
    },
    {
      "x": -4,
      "y": 0,
      "z": -4,
      "name": "Prototype_Rock_Concrete_Brick"
    },
    {
      "x": -4,
      "y": 0,
      "z": -3,
      "name": "Prototype_Rock_Concrete_Brick"
    },
    {
      "x": -4,
      "y": 0,
      "z": -2,
      "name": "Prototype_Rock_Concrete_Brick"
    },
    {
      "x": -4,
      "y": 1,
      "z": -2,
      "name": "Prototype_Rock_Concrete_Brick"
    },
    {
      "x": -4,
      "y": 2,
      "z": -2,
      "name": "Prototype_Rock_Concrete_Brick"
    },
    {
      "x": -4,
      "y": 3,
      "z": -2,
      "name": "Prototype_Rock_Concrete_Brick"
    },
    {
      "x": -4,
      "y": 4,
      "z": -2,
      "name": "Prototype_Rock_Concrete_Brick"
    },
    {
      "x": -4,
      "y": 5,
      "z": -2,
      "name": "Prototype_Rock_Concrete_Brick"
    },
    {
      "x": -3,
      "y": 0,
      "z": -7,
      "name": "Prototype_Rock_Concrete_Brick"
    },
    {
      "x": -3,
      "y": 0,
      "z": -6,
      "name": "Prototype_Rock_Concrete_Brick"
    },
    {
      "x": -3,
      "y": 0,
      "z": -5,
      "name": "Prototype_Rock_Concrete_Brick"
    },
    {
      "x": -3,
      "y": 0,
      "z": -4,
      "name": "Prototype_Rock_Concrete_Brick"
    },
    {
      "x": -3,
      "y": 0,
      "z": -3,
      "name": "Build_Lightsource_White",
      "rotation": 4
    },
    {
      "x": -3,
      "y": 0,
      "z": -2,
      "name": "Prototype_Rock_Concrete_Brick"
    },
    {
      "x": -3,
      "y": 1,
      "z": -2,
      "name": "Prototype_Rock_Concrete_Brick"
    },
    {
      "x": -3,
      "y": 2,
      "z": -2,
      "name": "Soil_Clay_Smooth_Black"
    },
    {
      "x": -3,
      "y": 3,
      "z": -2,
      "name": "Prototype_Rock_Concrete_Brick"
    },
    {
      "x": -3,
      "y": 4,
      "z": -2,
      "name": "Prototype_Rock_Concrete_Brick"
    },
    {
      "x": -3,
      "y": 5,
      "z": -2,
      "name": "Prototype_Rock_Concrete_Brick"
    },
    {
      "x": -3,
      "y": 0,
      "z": -1,
      "name": "Cloth_Block_Wool_White"
    },
    {
      "x": -3,
      "y": 0,
      "z": 0,
      "name": "Cloth_Block_Wool_White"
    },
    {
      "x": -3,
      "y": 0,
      "z": 1,
      "name": "Cloth_Block_Wool_White"
    },
    {
      "x": -3,
      "y": 0,
      "z": 2,
      "name": "Cloth_Block_Wool_White"
    },
    {
      "x": -3,
      "y": 0,
      "z": 3,
      "name": "Cloth_Block_Wool_White"
    },
    {
      "x": -3,
      "y": 0,
      "z": 4,
      "name": "Cloth_Block_Wool_White"
    },
    {
      "x": -3,
      "y": 0,
      "z": 5,
      "name": "Cloth_Block_Wool_White"
    },
    {
      "x": -3,
      "y": 0,
      "z": 6,
      "name": "Cloth_Block_Wool_White"
    },
    {
      "x": -3,
      "y": 0,
      "z": 7,
      "name": "Cloth_Block_Wool_White"
    },
    {
      "x": -3,
      "y": 0,
      "z": 8,
      "name": "Cloth_Block_Wool_White"
    },
    {
      "x": -2,
      "y": 0,
      "z": -7,
      "name": "Prototype_Rock_Concrete_Brick"
    },
    {
      "x": -2,
      "y": 0,
      "z": -6,
      "name": "Prototype_Rock_Concrete_Brick"
    },
    {
      "x": -2,
      "y": 0,
      "z": -5,
      "name": "Prototype_Rock_Concrete_Brick"
    },
    {
      "x": -2,
      "y": 0,
      "z": -4,
      "name": "Prototype_Rock_Concrete_Brick"
    },
    {
      "x": -2,
      "y": 0,
      "z": -3,
      "name": "Build_Lightsource_White",
      "rotation": 4
    },
    {
      "x": -2,
      "y": 0,
      "z": -2,
      "name": "Prototype_Rock_Concrete_Brick"
    },
    {
      "x": -2,
      "y": 1,
      "z": -2,
      "name": "Prototype_Rock_Concrete_Brick"
    },
    {
      "x": -2,
      "y": 2,
      "z": -2,
      "name": "Soil_Clay_Smooth_Black"
    },
    {
      "x": -2,
      "y": 3,
      "z": -2,
      "name": "Prototype_Rock_Concrete_Brick"
    },
    {
      "x": -2,
      "y": 4,
      "z": -2,
      "name": "Prototype_Rock_Concrete_Brick"
    },
    {
      "x": -2,
      "y": 5,
      "z": -2,
      "name": "Prototype_Rock_Concrete_Brick"
    },
    {
      "x": -2,
      "y": 0,
      "z": -1,
      "name": "Cloth_Block_Wool_Yellow"
    },
    {
      "x": -2,
      "y": 0,
      "z": 0,
      "name": "Cloth_Block_Wool_Yellow"
    },
    {
      "x": -2,
      "y": 0,
      "z": 1,
      "name": "Cloth_Block_Wool_Yellow"
    },
    {
      "x": -2,
      "y": 0,
      "z": 2,
      "name": "Cloth_Block_Wool_Yellow"
    },
    {
      "x": -2,
      "y": 0,
      "z": 3,
      "name": "Cloth_Block_Wool_Yellow"
    },
    {
      "x": -2,
      "y": 0,
      "z": 4,
      "name": "Cloth_Block_Wool_Yellow"
    },
    {
      "x": -2,
      "y": 0,
      "z": 5,
      "name": "Cloth_Block_Wool_Yellow"
    },
    {
      "x": -2,
      "y": 0,
      "z": 6,
      "name": "Cloth_Block_Wool_Yellow"
    },
    {
      "x": -2,
      "y": 0,
      "z": 7,
      "name": "Cloth_Block_Wool_Yellow"
    },
    {
      "x": -2,
      "y": 0,
      "z": 8,
      "name": "Cloth_Block_Wool_Yellow"
    },
    {
      "x": -1,
      "y": 0,
      "z": -7,
      "name": "Prototype_Rock_Concrete_Brick"
    },
    {
      "x": -1,
      "y": 0,
      "z": -6,
      "name": "Prototype_Rock_Concrete_Brick"
    },
    {
      "x": -1,
      "y": 0,
      "z": -5,
      "name": "Prototype_Rock_Concrete_Brick"
    },
    {
      "x": -1,
      "y": 0,
      "z": -4,
      "name": "Prototype_Rock_Concrete_Brick"
    },
    {
      "x": -1,
      "y": 0,
      "z": -3,
      "name": "Build_Lightsource_White",
      "rotation": 4
    },
    {
      "x": -1,
      "y": 0,
      "z": -2,
      "name": "Prototype_Rock_Concrete_Brick"
    },
    {
      "x": -1,
      "y": 1,
      "z": -2,
      "name": "Prototype_Rock_Concrete_Brick"
    },
    {
      "x": -1,
      "y": 2,
      "z": -2,
      "name": "Soil_Clay_Smooth_Black"
    },
    {
      "x": -1,
      "y": 3,
      "z": -2,
      "name": "Prototype_Rock_Concrete_Brick"
    },
    {
      "x": -1,
      "y": 4,
      "z": -2,
      "name": "Prototype_Rock_Concrete_Brick"
    },
    {
      "x": -1,
      "y": 5,
      "z": -2,
      "name": "Prototype_Rock_Concrete_Brick"
    },
    {
      "x": -1,
      "y": 0,
      "z": -1,
      "name": "Cloth_Block_Wool_Blue_Light"
    },
    {
      "x": -1,
      "y": 0,
      "z": 0,
      "name": "Cloth_Block_Wool_Blue_Light"
    },
    {
      "x": -1,
      "y": 0,
      "z": 1,
      "name": "Cloth_Block_Wool_Blue_Light"
    },
    {
      "x": -1,
      "y": 0,
      "z": 2,
      "name": "Cloth_Block_Wool_Blue_Light"
    },
    {
      "x": -1,
      "y": 0,
      "z": 3,
      "name": "Cloth_Block_Wool_Blue_Light"
    },
    {
      "x": -1,
      "y": 0,
      "z": 4,
      "name": "Cloth_Block_Wool_Blue_Light"
    },
    {
      "x": -1,
      "y": 0,
      "z": 5,
      "name": "Cloth_Block_Wool_Blue_Light"
    },
    {
      "x": -1,
      "y": 0,
      "z": 6,
      "name": "Cloth_Block_Wool_Blue_Light"
    },
    {
      "x": -1,
      "y": 0,
      "z": 7,
      "name": "Cloth_Block_Wool_Blue_Light"
    },
    {
      "x": -1,
      "y": 0,
      "z": 8,
      "name": "Cloth_Block_Wool_Blue_Light"
    },
    {
      "x": 0,
      "y": 0,
      "z": -7,
      "name": "Prototype_Rock_Concrete_Brick"
    },
    {
      "x": 0,
      "y": 0,
      "z": -6,
      "name": "Prototype_Rock_Concrete_Brick"
    },
    {
      "x": 0,
      "y": 0,
      "z": -5,
      "name": "Prototype_Rock_Concrete_Brick"
    },
    {
      "x": 0,
      "y": 0,
      "z": -4,
      "name": "Prototype_Rock_Concrete_Brick"
    },
    {
      "x": 0,
      "y": 0,
      "z": -3,
      "name": "Build_Lightsource_White",
      "rotation": 4
    },
    {
      "x": 0,
      "y": 0,
      "z": -2,
      "name": "Prototype_Rock_Concrete_Brick"
    },
    {
      "x": 0,
      "y": 1,
      "z": -2,
      "name": "Prototype_Rock_Concrete_Brick"
    },
    {
      "x": 0,
      "y": 2,
      "z": -2,
      "name": "Soil_Clay_Smooth_Black"
    },
    {
      "x": 0,
      "y": 3,
      "z": -2,
      "name": "Prototype_Rock_Concrete_Brick"
    },
    {
      "x": 0,
      "y": 4,
      "z": -2,
      "name": "Prototype_Rock_Concrete_Brick"
    },
    {
      "x": 0,
      "y": 5,
      "z": -2,
      "name": "Prototype_Rock_Concrete_Brick"
    },
    {
      "x": 0,
      "y": 0,
      "z": -1,
      "name": "Cloth_Block_Wool_Pink"
    },
    {
      "x": 0,
      "y": 0,
      "z": 0,
      "name": "Cloth_Block_Wool_Pink"
    },
    {
      "x": 0,
      "y": 0,
      "z": 1,
      "name": "Cloth_Block_Wool_Pink"
    },
    {
      "x": 0,
      "y": 0,
      "z": 2,
      "name": "Cloth_Block_Wool_Pink"
    },
    {
      "x": 0,
      "y": 0,
      "z": 3,
      "name": "Cloth_Block_Wool_Pink"
    },
    {
      "x": 0,
      "y": 0,
      "z": 4,
      "name": "Cloth_Block_Wool_Pink"
    },
    {
      "x": 0,
      "y": 0,
      "z": 5,
      "name": "Cloth_Block_Wool_Pink"
    },
    {
      "x": 0,
      "y": 0,
      "z": 6,
      "name": "Cloth_Block_Wool_Pink"
    },
    {
      "x": 0,
      "y": 0,
      "z": 7,
      "name": "Cloth_Block_Wool_Pink"
    },
    {
      "x": 0,
      "y": 0,
      "z": 8,
      "name": "Cloth_Block_Wool_Pink"
    },
    {
      "x": 1,
      "y": 0,
      "z": -7,
      "name": "Prototype_Rock_Concrete_Brick"
    },
    {
      "x": 1,
      "y": 0,
      "z": -6,
      "name": "Prototype_Rock_Concrete_Brick"
    },
    {
      "x": 1,
      "y": 0,
      "z": -5,
      "name": "Prototype_Rock_Concrete_Brick"
    },
    {
      "x": 1,
      "y": 0,
      "z": -4,
      "name": "Prototype_Rock_Concrete_Brick"
    },
    {
      "x": 1,
      "y": 0,
      "z": -3,
      "name": "Build_Lightsource_White",
      "rotation": 4
    },
    {
      "x": 1,
      "y": 0,
      "z": -2,
      "name": "Prototype_Rock_Concrete_Brick"
    },
    {
      "x": 1,
      "y": 1,
      "z": -2,
      "name": "Prototype_Rock_Concrete_Brick"
    },
    {
      "x": 1,
      "y": 2,
      "z": -2,
      "name": "Soil_Clay_Smooth_Black"
    },
    {
      "x": 1,
      "y": 3,
      "z": -2,
      "name": "Prototype_Rock_Concrete_Brick"
    },
    {
      "x": 1,
      "y": 4,
      "z": -2,
      "name": "Prototype_Rock_Concrete_Brick"
    },
    {
      "x": 1,
      "y": 5,
      "z": -2,
      "name": "Prototype_Rock_Concrete_Brick"
    },
    {
      "x": 1,
      "y": 0,
      "z": -1,
      "name": "Cloth_Block_Wool_Gray_Light"
    },
    {
      "x": 1,
      "y": 0,
      "z": 0,
      "name": "Cloth_Block_Wool_Gray_Light"
    },
    {
      "x": 1,
      "y": 0,
      "z": 1,
      "name": "Cloth_Block_Wool_Gray_Light"
    },
    {
      "x": 1,
      "y": 0,
      "z": 2,
      "name": "Cloth_Block_Wool_Gray_Light"
    },
    {
      "x": 1,
      "y": 0,
      "z": 3,
      "name": "Cloth_Block_Wool_Gray_Light"
    },
    {
      "x": 1,
      "y": 0,
      "z": 4,
      "name": "Cloth_Block_Wool_Gray_Light"
    },
    {
      "x": 1,
      "y": 0,
      "z": 5,
      "name": "Cloth_Block_Wool_Gray_Light"
    },
    {
      "x": 1,
      "y": 0,
      "z": 6,
      "name": "Cloth_Block_Wool_Gray_Light"
    },
    {
      "x": 1,
      "y": 0,
      "z": 7,
      "name": "Cloth_Block_Wool_Gray_Light"
    },
    {
      "x": 1,
      "y": 0,
      "z": 8,
      "name": "Cloth_Block_Wool_Gray_Light"
    },
    {
      "x": 2,
      "y": 0,
      "z": -7,
      "name": "Prototype_Rock_Concrete_Brick"
    },
    {
      "x": 2,
      "y": 0,
      "z": -6,
      "name": "Prototype_Rock_Concrete_Brick"
    },
    {
      "x": 2,
      "y": 0,
      "z": -5,
      "name": "Prototype_Rock_Concrete_Brick"
    },
    {
      "x": 2,
      "y": 0,
      "z": -4,
      "name": "Prototype_Rock_Concrete_Brick"
    },
    {
      "x": 2,
      "y": 0,
      "z": -3,
      "name": "Build_Lightsource_White",
      "rotation": 4
    },
    {
      "x": 2,
      "y": 0,
      "z": -2,
      "name": "Prototype_Rock_Concrete_Brick"
    },
    {
      "x": 2,
      "y": 1,
      "z": -2,
      "name": "Prototype_Rock_Concrete_Brick"
    },
    {
      "x": 2,
      "y": 2,
      "z": -2,
      "name": "Soil_Clay_Smooth_Black"
    },
    {
      "x": 2,
      "y": 3,
      "z": -2,
      "name": "Prototype_Rock_Concrete_Brick"
    },
    {
      "x": 2,
      "y": 4,
      "z": -2,
      "name": "Prototype_Rock_Concrete_Brick"
    },
    {
      "x": 2,
      "y": 5,
      "z": -2,
      "name": "Prototype_Rock_Concrete_Brick"
    },
    {
      "x": 2,
      "y": 0,
      "z": -1,
      "name": "Cloth_Block_Wool_Red"
    },
    {
      "x": 2,
      "y": 0,
      "z": 0,
      "name": "Cloth_Block_Wool_Red"
    },
    {
      "x": 2,
      "y": 0,
      "z": 1,
      "name": "Cloth_Block_Wool_Red"
    },
    {
      "x": 2,
      "y": 0,
      "z": 2,
      "name": "Cloth_Block_Wool_Red"
    },
    {
      "x": 2,
      "y": 0,
      "z": 3,
      "name": "Cloth_Block_Wool_Red"
    },
    {
      "x": 2,
      "y": 0,
      "z": 4,
      "name": "Cloth_Block_Wool_Red"
    },
    {
      "x": 2,
      "y": 0,
      "z": 5,
      "name": "Cloth_Block_Wool_Red"
    },
    {
      "x": 2,
      "y": 0,
      "z": 6,
      "name": "Cloth_Block_Wool_Red"
    },
    {
      "x": 2,
      "y": 0,
      "z": 7,
      "name": "Cloth_Block_Wool_Red"
    },
    {
      "x": 2,
      "y": 0,
      "z": 8,
      "name": "Cloth_Block_Wool_Red"
    },
    {
      "x": 3,
      "y": 0,
      "z": -7,
      "name": "Prototype_Rock_Concrete_Brick"
    },
    {
      "x": 3,
      "y": 0,
      "z": -6,
      "name": "Prototype_Rock_Concrete_Brick"
    },
    {
      "x": 3,
      "y": 0,
      "z": -5,
      "name": "Prototype_Rock_Concrete_Brick"
    },
    {
      "x": 3,
      "y": 0,
      "z": -4,
      "name": "Prototype_Rock_Concrete_Brick"
    },
    {
      "x": 3,
      "y": 0,
      "z": -3,
      "name": "Build_Lightsource_White",
      "rotation": 4
    },
    {
      "x": 3,
      "y": 0,
      "z": -2,
      "name": "Prototype_Rock_Concrete_Brick"
    },
    {
      "x": 3,
      "y": 1,
      "z": -2,
      "name": "Prototype_Rock_Concrete_Brick"
    },
    {
      "x": 3,
      "y": 2,
      "z": -2,
      "name": "Soil_Clay_Smooth_Black"
    },
    {
      "x": 3,
      "y": 3,
      "z": -2,
      "name": "Prototype_Rock_Concrete_Brick"
    },
    {
      "x": 3,
      "y": 4,
      "z": -2,
      "name": "Prototype_Rock_Concrete_Brick"
    },
    {
      "x": 3,
      "y": 5,
      "z": -2,
      "name": "Prototype_Rock_Concrete_Brick"
    },
    {
      "x": 3,
      "y": 0,
      "z": -1,
      "name": "Cloth_Block_Wool_Orange"
    },
    {
      "x": 3,
      "y": 0,
      "z": 0,
      "name": "Cloth_Block_Wool_Orange"
    },
    {
      "x": 3,
      "y": 0,
      "z": 1,
      "name": "Cloth_Block_Wool_Orange"
    },
    {
      "x": 3,
      "y": 0,
      "z": 2,
      "name": "Cloth_Block_Wool_Orange"
    },
    {
      "x": 3,
      "y": 0,
      "z": 3,
      "name": "Cloth_Block_Wool_Orange"
    },
    {
      "x": 3,
      "y": 0,
      "z": 4,
      "name": "Cloth_Block_Wool_Orange"
    },
    {
      "x": 3,
      "y": 0,
      "z": 5,
      "name": "Cloth_Block_Wool_Orange"
    },
    {
      "x": 3,
      "y": 0,
      "z": 6,
      "name": "Cloth_Block_Wool_Orange"
    },
    {
      "x": 3,
      "y": 0,
      "z": 7,
      "name": "Cloth_Block_Wool_Orange"
    },
    {
      "x": 3,
      "y": 0,
      "z": 8,
      "name": "Cloth_Block_Wool_Orange"
    },
    {
      "x": 4,
      "y": 0,
      "z": -7,
      "name": "Prototype_Rock_Concrete_Brick"
    },
    {
      "x": 4,
      "y": 0,
      "z": -6,
      "name": "Prototype_Rock_Concrete_Brick"
    },
    {
      "x": 4,
      "y": 0,
      "z": -5,
      "name": "Prototype_Rock_Concrete_Brick"
    },
    {
      "x": 4,
      "y": 0,
      "z": -4,
      "name": "Prototype_Rock_Concrete_Brick"
    },
    {
      "x": 4,
      "y": 0,
      "z": -3,
      "name": "Build_Lightsource_White",
      "rotation": 4
    },
    {
      "x": 4,
      "y": 0,
      "z": -2,
      "name": "Prototype_Rock_Concrete_Brick"
    },
    {
      "x": 4,
      "y": 1,
      "z": -2,
      "name": "Prototype_Rock_Concrete_Brick"
    },
    {
      "x": 4,
      "y": 2,
      "z": -2,
      "name": "Soil_Clay_Smooth_Black"
    },
    {
      "x": 4,
      "y": 3,
      "z": -2,
      "name": "Prototype_Rock_Concrete_Brick"
    },
    {
      "x": 4,
      "y": 4,
      "z": -2,
      "name": "Prototype_Rock_Concrete_Brick"
    },
    {
      "x": 4,
      "y": 5,
      "z": -2,
      "name": "Prototype_Rock_Concrete_Brick"
    },
    {
      "x": 4,
      "y": 0,
      "z": -1,
      "name": "Cloth_Block_Wool_Blue"
    },
    {
      "x": 4,
      "y": 0,
      "z": 0,
      "name": "Cloth_Block_Wool_Blue"
    },
    {
      "x": 4,
      "y": 0,
      "z": 1,
      "name": "Cloth_Block_Wool_Blue"
    },
    {
      "x": 4,
      "y": 0,
      "z": 2,
      "name": "Cloth_Block_Wool_Blue"
    },
    {
      "x": 4,
      "y": 0,
      "z": 3,
      "name": "Cloth_Block_Wool_Blue"
    },
    {
      "x": 4,
      "y": 0,
      "z": 4,
      "name": "Cloth_Block_Wool_Blue"
    },
    {
      "x": 4,
      "y": 0,
      "z": 5,
      "name": "Cloth_Block_Wool_Blue"
    },
    {
      "x": 4,
      "y": 0,
      "z": 6,
      "name": "Cloth_Block_Wool_Blue"
    },
    {
      "x": 4,
      "y": 0,
      "z": 7,
      "name": "Cloth_Block_Wool_Blue"
    },
    {
      "x": 4,
      "y": 0,
      "z": 8,
      "name": "Cloth_Block_Wool_Blue"
    },
    {
      "x": 5,
      "y": 0,
      "z": -7,
      "name": "Prototype_Rock_Concrete_Brick"
    },
    {
      "x": 5,
      "y": 0,
      "z": -6,
      "name": "Prototype_Rock_Concrete_Brick"
    },
    {
      "x": 5,
      "y": 0,
      "z": -5,
      "name": "Prototype_Rock_Concrete_Brick"
    },
    {
      "x": 5,
      "y": 0,
      "z": -4,
      "name": "Prototype_Rock_Concrete_Brick"
    },
    {
      "x": 5,
      "y": 0,
      "z": -3,
      "name": "Prototype_Rock_Concrete_Brick"
    },
    {
      "x": 5,
      "y": 0,
      "z": -2,
      "name": "Prototype_Rock_Concrete_Brick"
    },
    {
      "x": 5,
      "y": 1,
      "z": -2,
      "name": "Prototype_Rock_Concrete_Brick"
    },
    {
      "x": 5,
      "y": 2,
      "z": -2,
      "name": "Prototype_Rock_Concrete_Brick"
    },
    {
      "x": 5,
      "y": 3,
      "z": -2,
      "name": "Prototype_Rock_Concrete_Brick"
    },
    {
      "x": 5,
      "y": 4,
      "z": -2,
      "name": "Prototype_Rock_Concrete_Brick"
    },
    {
      "x": 5,
      "y": 5,
      "z": -2,
      "name": "Prototype_Rock_Concrete_Brick"
    }
  ],
  "fluids": [
    {
      "x": -5,
      "y": 0,
      "z": -7,
      "name": "Empty",
      "level": 0
    },
    {
      "x": -5,
      "y": 1,
      "z": -7,
      "name": "Empty",
      "level": 0
    },
    {
      "x": -5,
      "y": 2,
      "z": -7,
      "name": "Empty",
      "level": 0
    },
    {
      "x": -5,
      "y": 3,
      "z": -7,
      "name": "Empty",
      "level": 0
    },
    {
      "x": -5,
      "y": 4,
      "z": -7,
      "name": "Empty",
      "level": 0
    },
    {
      "x": -5,
      "y": 5,
      "z": -7,
      "name": "Empty",
      "level": 0
    },
    {
      "x": -5,
      "y": 0,
      "z": -6,
      "name": "Empty",
      "level": 0
    },
    {
      "x": -5,
      "y": 1,
      "z": -6,
      "name": "Empty",
      "level": 0
    },
    {
      "x": -5,
      "y": 2,
      "z": -6,
      "name": "Empty",
      "level": 0
    },
    {
      "x": -5,
      "y": 3,
      "z": -6,
      "name": "Empty",
      "level": 0
    },
    {
      "x": -5,
      "y": 4,
      "z": -6,
      "name": "Empty",
      "level": 0
    },
    {
      "x": -5,
      "y": 5,
      "z": -6,
      "name": "Empty",
      "level": 0
    },
    {
      "x": -5,
      "y": 0,
      "z": -5,
      "name": "Empty",
      "level": 0
    },
    {
      "x": -5,
      "y": 1,
      "z": -5,
      "name": "Empty",
      "level": 0
    },
    {
      "x": -5,
      "y": 2,
      "z": -5,
      "name": "Empty",
      "level": 0
    },
    {
      "x": -5,
      "y": 3,
      "z": -5,
      "name": "Empty",
      "level": 0
    },
    {
      "x": -5,
      "y": 4,
      "z": -5,
      "name": "Empty",
      "level": 0
    },
    {
      "x": -5,
      "y": 5,
      "z": -5,
      "name": "Empty",
      "level": 0
    },
    {
      "x": -5,
      "y": 0,
      "z": -4,
      "name": "Empty",
      "level": 0
    },
    {
      "x": -5,
      "y": 1,
      "z": -4,
      "name": "Empty",
      "level": 0
    },
    {
      "x": -5,
      "y": 2,
      "z": -4,
      "name": "Empty",
      "level": 0
    },
    {
      "x": -5,
      "y": 3,
      "z": -4,
      "name": "Empty",
      "level": 0
    },
    {
      "x": -5,
      "y": 4,
      "z": -4,
      "name": "Empty",
      "level": 0
    },
    {
      "x": -5,
      "y": 5,
      "z": -4,
      "name": "Empty",
      "level": 0
    },
    {
      "x": -5,
      "y": 0,
      "z": -3,
      "name": "Empty",
      "level": 0
    },
    {
      "x": -5,
      "y": 1,
      "z": -3,
      "name": "Empty",
      "level": 0
    },
    {
      "x": -5,
      "y": 2,
      "z": -3,
      "name": "Empty",
      "level": 0
    },
    {
      "x": -5,
      "y": 3,
      "z": -3,
      "name": "Empty",
      "level": 0
    },
    {
      "x": -5,
      "y": 4,
      "z": -3,
      "name": "Empty",
      "level": 0
    },
    {
      "x": -5,
      "y": 5,
      "z": -3,
      "name": "Empty",
      "level": 0
    },
    {
      "x": -5,
      "y": 0,
      "z": -2,
      "name": "Empty",
      "level": 0
    },
    {
      "x": -5,
      "y": 1,
      "z": -2,
      "name": "Empty",
      "level": 0
    },
    {
      "x": -5,
      "y": 2,
      "z": -2,
      "name": "Empty",
      "level": 0
    },
    {
      "x": -5,
      "y": 3,
      "z": -2,
      "name": "Empty",
      "level": 0
    },
    {
      "x": -5,
      "y": 4,
      "z": -2,
      "name": "Empty",
      "level": 0
    },
    {
      "x": -5,
      "y": 5,
      "z": -2,
      "name": "Empty",
      "level": 0
    },
    {
      "x": -4,
      "y": 0,
      "z": -7,
      "name": "Empty",
      "level": 0
    },
    {
      "x": -4,
      "y": 0,
      "z": -6,
      "name": "Empty",
      "level": 0
    },
    {
      "x": -4,
      "y": 0,
      "z": -5,
      "name": "Empty",
      "level": 0
    },
    {
      "x": -4,
      "y": 0,
      "z": -4,
      "name": "Empty",
      "level": 0
    },
    {
      "x": -4,
      "y": 0,
      "z": -3,
      "name": "Empty",
      "level": 0
    },
    {
      "x": -4,
      "y": 0,
      "z": -2,
      "name": "Empty",
      "level": 0
    },
    {
      "x": -4,
      "y": 1,
      "z": -2,
      "name": "Empty",
      "level": 0
    },
    {
      "x": -4,
      "y": 2,
      "z": -2,
      "name": "Empty",
      "level": 0
    },
    {
      "x": -4,
      "y": 3,
      "z": -2,
      "name": "Empty",
      "level": 0
    },
    {
      "x": -4,
      "y": 4,
      "z": -2,
      "name": "Empty",
      "level": 0
    },
    {
      "x": -4,
      "y": 5,
      "z": -2,
      "name": "Empty",
      "level": 0
    },
    {
      "x": -3,
      "y": 0,
      "z": -7,
      "name": "Empty",
      "level": 0
    },
    {
      "x": -3,
      "y": 0,
      "z": -6,
      "name": "Empty",
      "level": 0
    },
    {
      "x": -3,
      "y": 0,
      "z": -5,
      "name": "Empty",
      "level": 0
    },
    {
      "x": -3,
      "y": 0,
      "z": -4,
      "name": "Empty",
      "level": 0
    },
    {
      "x": -3,
      "y": 0,
      "z": -3,
      "name": "Empty",
      "level": 0
    },
    {
      "x": -3,
      "y": 0,
      "z": -2,
      "name": "Empty",
      "level": 0
    },
    {
      "x": -3,
      "y": 1,
      "z": -2,
      "name": "Empty",
      "level": 0
    },
    {
      "x": -3,
      "y": 2,
      "z": -2,
      "name": "Empty",
      "level": 0
    },
    {
      "x": -3,
      "y": 3,
      "z": -2,
      "name": "Empty",
      "level": 0
    },
    {
      "x": -3,
      "y": 4,
      "z": -2,
      "name": "Empty",
      "level": 0
    },
    {
      "x": -3,
      "y": 5,
      "z": -2,
      "name": "Empty",
      "level": 0
    },
    {
      "x": -3,
      "y": 0,
      "z": -1,
      "name": "Empty",
      "level": 0
    },
    {
      "x": -3,
      "y": 0,
      "z": 0,
      "name": "Empty",
      "level": 0
    },
    {
      "x": -3,
      "y": 0,
      "z": 1,
      "name": "Empty",
      "level": 0
    },
    {
      "x": -3,
      "y": 0,
      "z": 2,
      "name": "Empty",
      "level": 0
    },
    {
      "x": -3,
      "y": 0,
      "z": 3,
      "name": "Empty",
      "level": 0
    },
    {
      "x": -3,
      "y": 0,
      "z": 4,
      "name": "Empty",
      "level": 0
    },
    {
      "x": -3,
      "y": 0,
      "z": 5,
      "name": "Empty",
      "level": 0
    },
    {
      "x": -3,
      "y": 0,
      "z": 6,
      "name": "Empty",
      "level": 0
    },
    {
      "x": -3,
      "y": 0,
      "z": 7,
      "name": "Empty",
      "level": 0
    },
    {
      "x": -3,
      "y": 0,
      "z": 8,
      "name": "Empty",
      "level": 0
    },
    {
      "x": -2,
      "y": 0,
      "z": -7,
      "name": "Empty",
      "level": 0
    },
    {
      "x": -2,
      "y": 0,
      "z": -6,
      "name": "Empty",
      "level": 0
    },
    {
      "x": -2,
      "y": 0,
      "z": -5,
      "name": "Empty",
      "level": 0
    },
    {
      "x": -2,
      "y": 0,
      "z": -4,
      "name": "Empty",
      "level": 0
    },
    {
      "x": -2,
      "y": 0,
      "z": -3,
      "name": "Empty",
      "level": 0
    },
    {
      "x": -2,
      "y": 0,
      "z": -2,
      "name": "Empty",
      "level": 0
    },
    {
      "x": -2,
      "y": 1,
      "z": -2,
      "name": "Empty",
      "level": 0
    },
    {
      "x": -2,
      "y": 2,
      "z": -2,
      "name": "Empty",
      "level": 0
    },
    {
      "x": -2,
      "y": 3,
      "z": -2,
      "name": "Empty",
      "level": 0
    },
    {
      "x": -2,
      "y": 4,
      "z": -2,
      "name": "Empty",
      "level": 0
    },
    {
      "x": -2,
      "y": 5,
      "z": -2,
      "name": "Empty",
      "level": 0
    },
    {
      "x": -2,
      "y": 0,
      "z": -1,
      "name": "Empty",
      "level": 0
    },
    {
      "x": -2,
      "y": 0,
      "z": 0,
      "name": "Empty",
      "level": 0
    },
    {
      "x": -2,
      "y": 0,
      "z": 1,
      "name": "Empty",
      "level": 0
    },
    {
      "x": -2,
      "y": 0,
      "z": 2,
      "name": "Empty",
      "level": 0
    },
    {
      "x": -2,
      "y": 0,
      "z": 3,
      "name": "Empty",
      "level": 0
    },
    {
      "x": -2,
      "y": 0,
      "z": 4,
      "name": "Empty",
      "level": 0
    },
    {
      "x": -2,
      "y": 0,
      "z": 5,
      "name": "Empty",
      "level": 0
    },
    {
      "x": -2,
      "y": 0,
      "z": 6,
      "name": "Empty",
      "level": 0
    },
    {
      "x": -2,
      "y": 0,
      "z": 7,
      "name": "Empty",
      "level": 0
    },
    {
      "x": -2,
      "y": 0,
      "z": 8,
      "name": "Empty",
      "level": 0
    },
    {
      "x": -1,
      "y": 0,
      "z": -7,
      "name": "Empty",
      "level": 0
    },
    {
      "x": -1,
      "y": 0,
      "z": -6,
      "name": "Empty",
      "level": 0
    },
    {
      "x": -1,
      "y": 0,
      "z": -5,
      "name": "Empty",
      "level": 0
    },
    {
      "x": -1,
      "y": 0,
      "z": -4,
      "name": "Empty",
      "level": 0
    },
    {
      "x": -1,
      "y": 0,
      "z": -3,
      "name": "Empty",
      "level": 0
    },
    {
      "x": -1,
      "y": 0,
      "z": -2,
      "name": "Empty",
      "level": 0
    },
    {
      "x": -1,
      "y": 1,
      "z": -2,
      "name": "Empty",
      "level": 0
    },
    {
      "x": -1,
      "y": 2,
      "z": -2,
      "name": "Empty",
      "level": 0
    },
    {
      "x": -1,
      "y": 3,
      "z": -2,
      "name": "Empty",
      "level": 0
    },
    {
      "x": -1,
      "y": 4,
      "z": -2,
      "name": "Empty",
      "level": 0
    },
    {
      "x": -1,
      "y": 5,
      "z": -2,
      "name": "Empty",
      "level": 0
    },
    {
      "x": -1,
      "y": 0,
      "z": -1,
      "name": "Empty",
      "level": 0
    },
    {
      "x": -1,
      "y": 0,
      "z": 0,
      "name": "Empty",
      "level": 0
    },
    {
      "x": -1,
      "y": 0,
      "z": 1,
      "name": "Empty",
      "level": 0
    },
    {
      "x": -1,
      "y": 0,
      "z": 2,
      "name": "Empty",
      "level": 0
    },
    {
      "x": -1,
      "y": 0,
      "z": 3,
      "name": "Empty",
      "level": 0
    },
    {
      "x": -1,
      "y": 0,
      "z": 4,
      "name": "Empty",
      "level": 0
    },
    {
      "x": -1,
      "y": 0,
      "z": 5,
      "name": "Empty",
      "level": 0
    },
    {
      "x": -1,
      "y": 0,
      "z": 6,
      "name": "Empty",
      "level": 0
    },
    {
      "x": -1,
      "y": 0,
      "z": 7,
      "name": "Empty",
      "level": 0
    },
    {
      "x": -1,
      "y": 0,
      "z": 8,
      "name": "Empty",
      "level": 0
    },
    {
      "x": 0,
      "y": 0,
      "z": -7,
      "name": "Empty",
      "level": 0
    },
    {
      "x": 0,
      "y": 0,
      "z": -6,
      "name": "Empty",
      "level": 0
    },
    {
      "x": 0,
      "y": 0,
      "z": -5,
      "name": "Empty",
      "level": 0
    },
    {
      "x": 0,
      "y": 0,
      "z": -4,
      "name": "Empty",
      "level": 0
    },
    {
      "x": 0,
      "y": 0,
      "z": -3,
      "name": "Empty",
      "level": 0
    },
    {
      "x": 0,
      "y": 0,
      "z": -2,
      "name": "Empty",
      "level": 0
    },
    {
      "x": 0,
      "y": 1,
      "z": -2,
      "name": "Empty",
      "level": 0
    },
    {
      "x": 0,
      "y": 2,
      "z": -2,
      "name": "Empty",
      "level": 0
    },
    {
      "x": 0,
      "y": 3,
      "z": -2,
      "name": "Empty",
      "level": 0
    },
    {
      "x": 0,
      "y": 4,
      "z": -2,
      "name": "Empty",
      "level": 0
    },
    {
      "x": 0,
      "y": 5,
      "z": -2,
      "name": "Empty",
      "level": 0
    },
    {
      "x": 0,
      "y": 0,
      "z": -1,
      "name": "Empty",
      "level": 0
    },
    {
      "x": 0,
      "y": 0,
      "z": 0,
      "name": "Empty",
      "level": 0
    },
    {
      "x": 0,
      "y": 0,
      "z": 1,
      "name": "Empty",
      "level": 0
    },
    {
      "x": 0,
      "y": 0,
      "z": 2,
      "name": "Empty",
      "level": 0
    },
    {
      "x": 0,
      "y": 0,
      "z": 3,
      "name": "Empty",
      "level": 0
    },
    {
      "x": 0,
      "y": 0,
      "z": 4,
      "name": "Empty",
      "level": 0
    },
    {
      "x": 0,
      "y": 0,
      "z": 5,
      "name": "Empty",
      "level": 0
    },
    {
      "x": 0,
      "y": 0,
      "z": 6,
      "name": "Empty",
      "level": 0
    },
    {
      "x": 0,
      "y": 0,
      "z": 7,
      "name": "Empty",
      "level": 0
    },
    {
      "x": 0,
      "y": 0,
      "z": 8,
      "name": "Empty",
      "level": 0
    },
    {
      "x": 1,
      "y": 0,
      "z": -7,
      "name": "Empty",
      "level": 0
    },
    {
      "x": 1,
      "y": 0,
      "z": -6,
      "name": "Empty",
      "level": 0
    },
    {
      "x": 1,
      "y": 0,
      "z": -5,
      "name": "Empty",
      "level": 0
    },
    {
      "x": 1,
      "y": 0,
      "z": -4,
      "name": "Empty",
      "level": 0
    },
    {
      "x": 1,
      "y": 0,
      "z": -3,
      "name": "Empty",
      "level": 0
    },
    {
      "x": 1,
      "y": 0,
      "z": -2,
      "name": "Empty",
      "level": 0
    },
    {
      "x": 1,
      "y": 1,
      "z": -2,
      "name": "Empty",
      "level": 0
    },
    {
      "x": 1,
      "y": 2,
      "z": -2,
      "name": "Empty",
      "level": 0
    },
    {
      "x": 1,
      "y": 3,
      "z": -2,
      "name": "Empty",
      "level": 0
    },
    {
      "x": 1,
      "y": 4,
      "z": -2,
      "name": "Empty",
      "level": 0
    },
    {
      "x": 1,
      "y": 5,
      "z": -2,
      "name": "Empty",
      "level": 0
    },
    {
      "x": 1,
      "y": 0,
      "z": -1,
      "name": "Empty",
      "level": 0
    },
    {
      "x": 1,
      "y": 0,
      "z": 0,
      "name": "Empty",
      "level": 0
    },
    {
      "x": 1,
      "y": 0,
      "z": 1,
      "name": "Empty",
      "level": 0
    },
    {
      "x": 1,
      "y": 0,
      "z": 2,
      "name": "Empty",
      "level": 0
    },
    {
      "x": 1,
      "y": 0,
      "z": 3,
      "name": "Empty",
      "level": 0
    },
    {
      "x": 1,
      "y": 0,
      "z": 4,
      "name": "Empty",
      "level": 0
    },
    {
      "x": 1,
      "y": 0,
      "z": 5,
      "name": "Empty",
      "level": 0
    },
    {
      "x": 1,
      "y": 0,
      "z": 6,
      "name": "Empty",
      "level": 0
    },
    {
      "x": 1,
      "y": 0,
      "z": 7,
      "name": "Empty",
      "level": 0
    },
    {
      "x": 1,
      "y": 0,
      "z": 8,
      "name": "Empty",
      "level": 0
    },
    {
      "x": 2,
      "y": 0,
      "z": -7,
      "name": "Empty",
      "level": 0
    },
    {
      "x": 2,
      "y": 0,
      "z": -6,
      "name": "Empty",
      "level": 0
    },
    {
      "x": 2,
      "y": 0,
      "z": -5,
      "name": "Empty",
      "level": 0
    },
    {
      "x": 2,
      "y": 0,
      "z": -4,
      "name": "Empty",
      "level": 0
    },
    {
      "x": 2,
      "y": 0,
      "z": -3,
      "name": "Empty",
      "level": 0
    },
    {
      "x": 2,
      "y": 0,
      "z": -2,
      "name": "Empty",
      "level": 0
    },
    {
      "x": 2,
      "y": 1,
      "z": -2,
      "name": "Empty",
      "level": 0
    },
    {
      "x": 2,
      "y": 2,
      "z": -2,
      "name": "Empty",
      "level": 0
    },
    {
      "x": 2,
      "y": 3,
      "z": -2,
      "name": "Empty",
      "level": 0
    },
    {
      "x": 2,
      "y": 4,
      "z": -2,
      "name": "Empty",
      "level": 0
    },
    {
      "x": 2,
      "y": 5,
      "z": -2,
      "name": "Empty",
      "level": 0
    },
    {
      "x": 2,
      "y": 0,
      "z": -1,
      "name": "Empty",
      "level": 0
    },
    {
      "x": 2,
      "y": 0,
      "z": 0,
      "name": "Empty",
      "level": 0
    },
    {
      "x": 2,
      "y": 0,
      "z": 1,
      "name": "Empty",
      "level": 0
    },
    {
      "x": 2,
      "y": 0,
      "z": 2,
      "name": "Empty",
      "level": 0
    },
    {
      "x": 2,
      "y": 0,
      "z": 3,
      "name": "Empty",
      "level": 0
    },
    {
      "x": 2,
      "y": 0,
      "z": 4,
      "name": "Empty",
      "level": 0
    },
    {
      "x": 2,
      "y": 0,
      "z": 5,
      "name": "Empty",
      "level": 0
    },
    {
      "x": 2,
      "y": 0,
      "z": 6,
      "name": "Empty",
      "level": 0
    },
    {
      "x": 2,
      "y": 0,
      "z": 7,
      "name": "Empty",
      "level": 0
    },
    {
      "x": 2,
      "y": 0,
      "z": 8,
      "name": "Empty",
      "level": 0
    },
    {
      "x": 3,
      "y": 0,
      "z": -7,
      "name": "Empty",
      "level": 0
    },
    {
      "x": 3,
      "y": 0,
      "z": -6,
      "name": "Empty",
      "level": 0
    },
    {
      "x": 3,
      "y": 0,
      "z": -5,
      "name": "Empty",
      "level": 0
    },
    {
      "x": 3,
      "y": 0,
      "z": -4,
      "name": "Empty",
      "level": 0
    },
    {
      "x": 3,
      "y": 0,
      "z": -3,
      "name": "Empty",
      "level": 0
    },
    {
      "x": 3,
      "y": 0,
      "z": -2,
      "name": "Empty",
      "level": 0
    },
    {
      "x": 3,
      "y": 1,
      "z": -2,
      "name": "Empty",
      "level": 0
    },
    {
      "x": 3,
      "y": 2,
      "z": -2,
      "name": "Empty",
      "level": 0
    },
    {
      "x": 3,
      "y": 3,
      "z": -2,
      "name": "Empty",
      "level": 0
    },
    {
      "x": 3,
      "y": 4,
      "z": -2,
      "name": "Empty",
      "level": 0
    },
    {
      "x": 3,
      "y": 5,
      "z": -2,
      "name": "Empty",
      "level": 0
    },
    {
      "x": 3,
      "y": 0,
      "z": -1,
      "name": "Empty",
      "level": 0
    },
    {
      "x": 3,
      "y": 0,
      "z": 0,
      "name": "Empty",
      "level": 0
    },
    {
      "x": 3,
      "y": 0,
      "z": 1,
      "name": "Empty",
      "level": 0
    },
    {
      "x": 3,
      "y": 0,
      "z": 2,
      "name": "Empty",
      "level": 0
    },
    {
      "x": 3,
      "y": 0,
      "z": 3,
      "name": "Empty",
      "level": 0
    },
    {
      "x": 3,
      "y": 0,
      "z": 4,
      "name": "Empty",
      "level": 0
    },
    {
      "x": 3,
      "y": 0,
      "z": 5,
      "name": "Empty",
      "level": 0
    },
    {
      "x": 3,
      "y": 0,
      "z": 6,
      "name": "Empty",
      "level": 0
    },
    {
      "x": 3,
      "y": 0,
      "z": 7,
      "name": "Empty",
      "level": 0
    },
    {
      "x": 3,
      "y": 0,
      "z": 8,
      "name": "Empty",
      "level": 0
    },
    {
      "x": 4,
      "y": 0,
      "z": -7,
      "name": "Empty",
      "level": 0
    },
    {
      "x": 4,
      "y": 0,
      "z": -6,
      "name": "Empty",
      "level": 0
    },
    {
      "x": 4,
      "y": 0,
      "z": -5,
      "name": "Empty",
      "level": 0
    },
    {
      "x": 4,
      "y": 0,
      "z": -4,
      "name": "Empty",
      "level": 0
    },
    {
      "x": 4,
      "y": 0,
      "z": -3,
      "name": "Empty",
      "level": 0
    },
    {
      "x": 4,
      "y": 0,
      "z": -2,
      "name": "Empty",
      "level": 0
    },
    {
      "x": 4,
      "y": 1,
      "z": -2,
      "name": "Empty",
      "level": 0
    },
    {
      "x": 4,
      "y": 2,
      "z": -2,
      "name": "Empty",
      "level": 0
    },
    {
      "x": 4,
      "y": 3,
      "z": -2,
      "name": "Empty",
      "level": 0
    },
    {
      "x": 4,
      "y": 4,
      "z": -2,
      "name": "Empty",
      "level": 0
    },
    {
      "x": 4,
      "y": 5,
      "z": -2,
      "name": "Empty",
      "level": 0
    },
    {
      "x": 4,
      "y": 0,
      "z": -1,
      "name": "Empty",
      "level": 0
    },
    {
      "x": 4,
      "y": 0,
      "z": 0,
      "name": "Empty",
      "level": 0
    },
    {
      "x": 4,
      "y": 0,
      "z": 1,
      "name": "Empty",
      "level": 0
    },
    {
      "x": 4,
      "y": 0,
      "z": 2,
      "name": "Empty",
      "level": 0
    },
    {
      "x": 4,
      "y": 0,
      "z": 3,
      "name": "Empty",
      "level": 0
    },
    {
      "x": 4,
      "y": 0,
      "z": 4,
      "name": "Empty",
      "level": 0
    },
    {
      "x": 4,
      "y": 0,
      "z": 5,
      "name": "Empty",
      "level": 0
    },
    {
      "x": 4,
      "y": 0,
      "z": 6,
      "name": "Empty",
      "level": 0
    },
    {
      "x": 4,
      "y": 0,
      "z": 7,
      "name": "Empty",
      "level": 0
    },
    {
      "x": 4,
      "y": 0,
      "z": 8,
      "name": "Empty",
      "level": 0
    },
    {
      "x": 5,
      "y": 0,
      "z": -7,
      "name": "Empty",
      "level": 0
    },
    {
      "x": 5,
      "y": 0,
      "z": -6,
      "name": "Empty",
      "level": 0
    },
    {
      "x": 5,
      "y": 0,
      "z": -5,
      "name": "Empty",
      "level": 0
    },
    {
      "x": 5,
      "y": 0,
      "z": -4,
      "name": "Empty",
      "level": 0
    },
    {
      "x": 5,
      "y": 0,
      "z": -3,
      "name": "Empty",
      "level": 0
    },
    {
      "x": 5,
      "y": 0,
      "z": -2,
      "name": "Empty",
      "level": 0
    },
    {
      "x": 5,
      "y": 1,
      "z": -2,
      "name": "Empty",
      "level": 0
    },
    {
      "x": 5,
      "y": 2,
      "z": -2,
      "name": "Empty",
      "level": 0
    },
    {
      "x": 5,
      "y": 3,
      "z": -2,
      "name": "Empty",
      "level": 0
    },
    {
      "x": 5,
      "y": 4,
      "z": -2,
      "name": "Empty",
      "level": 0
    },
    {
      "x": 5,
      "y": 5,
      "z": -2,
      "name": "Empty",
      "level": 0
    }
  ],
  "entities": [
    {
      "Components": {
        "Transform": {
          "Position": {
            "X": 1.5,
            "Y": 1.0,
            "Z": 4.0
          },
          "Rotation": {
            "Pitch": 0.0,
            "Yaw": 0.0,
            "Roll": 0.0
          }
        },
        "TriggerVolumeGroup": {
          "GroupLinkId": "cdd9a5b8-9518-4155-ba8a-d8e6bd1449b1",
          "TargetTypes": [
            "Player"
          ],
          "Enabled": true,
          "Color": 4239424
        }
      }
    },
    {
      "Components": {
        "Transform": {
          "Position": {
            "X": 1.5,
            "Y": 1.0,
            "Z": -0.5
          },
          "Rotation": {
            "Pitch": 0.0,
            "Yaw": 0.0,
            "Roll": 0.0
          }
        },
        "TriggerVolume": {
          "Shape": {
            "Type": "Box",
            "Min": {
              "X": -0.5,
              "Y": -0.25,
              "Z": -0.5
            },
            "Max": {
              "X": 0.5,
              "Y": 0.25,
              "Z": 0.5
            }
          },
          "Effects": [
            {
              "Type": "ModifyTags",
              "Event": "TAG_ADDED",
              "Interval": 0.0,
              "Delay": 0.0,
              "Operation": "Set",
              "TagKey": "Shift",
              "TagValue": "Empty",
              "MatchKey": "ID",
              "MatchValue": "ShiftCalc5",
              "Radius": 20.0,
              "Center": "Volume"
            },
            {
              "Type": "ModifyTags",
              "Event": "TAG_ADDED",
              "Interval": 0.0,
              "Delay": 0.10000000149011612,
              "Operation": "Remove",
              "TagKey": "Shift",
              "TagValue": "",
              "MatchKey": "",
              "MatchValue": "",
              "Radius": 1.0,
              "Center": "Volume"
            },
            {
              "Type": "ModifyTags",
              "Event": "TAG_ADDED",
              "Interval": 0.0,
              "Delay": 0.10000000149011612,
              "Operation": "Set",
              "TagKey": "DisplayNumber",
              "TagValue": "0",
              "MatchKey": "ID",
              "MatchValue": "Display5",
              "Radius": 15.0,
              "Center": "Volume"
            },
            {
              "Type": "PlaceBlock",
              "Event": "TAG_ADDED",
              "Interval": 0.0,
              "Delay": 0.10000000149011612,
              "BlockType": "Cloth_Block_Wool_White",
              "Position": {
                "X": 0.0,
                "Y": 1.0,
                "Z": -1.0
              },
              "Origin": "VolumeOrigin",
              "ReplaceMode": "Always"
            }
          ],
          "Conditions": [
            {
              "Type": "TagCondition",
              "Event": "TAG_ADDED",
              "Source": "Radius",
              "TagKey": "DisplayNumber",
              "TagValue": "0",
              "MatchKey": "ID",
              "MatchValue": "Display4",
              "Radius": 15.0,
              "Center": "Volume"
            }
          ],
          "RejectionEffects": [
            {
              "Type": "ModifyTags",
              "Event": "TAG_ADDED",
              "Interval": 0.0,
              "Delay": 0.0,
              "Operation": "Remove",
              "TagKey": "Shift",
              "TagValue": "",
              "MatchKey": "",
              "MatchValue": "",
              "Radius": 1.0,
              "Center": "Volume"
            }
          ],
          "Enabled": true,
          "TargetTypes": [
            "Player"
          ],
          "Tags": {
            "ID": "ShiftCalc4"
          },
          "KeepLoaded": false,
          "GroupLinkId": "cdd9a5b8-9518-4155-ba8a-d8e6bd1449b1",
          "PrefabIndex": 0
        }
      }
    },
    {
      "Components": {
        "Transform": {
          "Position": {
            "X": 0.5,
            "Y": 1.0,
            "Z": 4.0
          },
          "Rotation": {
            "Pitch": 0.0,
            "Yaw": 0.0,
            "Roll": 0.0
          }
        },
        "TriggerVolumeGroup": {
          "GroupLinkId": "20ecfec7-f1d2-4c1d-a6e1-65726c14fec4",
          "TargetTypes": [
            "Player"
          ],
          "Enabled": true,
          "Color": 4239424
        }
      }
    },
    {
      "Components": {
        "Transform": {
          "Position": {
            "X": 0.5,
            "Y": 1.0,
            "Z": 5.5
          },
          "Rotation": {
            "Pitch": 0.0,
            "Yaw": 0.0,
            "Roll": 0.0
          }
        },
        "TriggerVolume": {
          "Shape": {
            "Type": "Box",
            "Min": {
              "X": -0.5,
              "Y": -0.25,
              "Z": -0.5
            },
            "Max": {
              "X": 0.5,
              "Y": 0.25,
              "Z": 0.5
            }
          },
          "Effects": [
            {
              "Type": "ModifyTags",
              "Event": "TAG_ADDED",
              "Interval": 0.0,
              "Delay": 0.0,
              "Operation": "Set",
              "TagKey": "Shift",
              "TagValue": "Empty",
              "MatchKey": "ID",
              "MatchValue": "ShiftCalc4",
              "Radius": 20.0,
              "Center": "Volume"
            },
            {
              "Type": "ModifyTags",
              "Event": "TAG_ADDED",
              "Interval": 0.0,
              "Delay": 0.10000000149011612,
              "Operation": "Remove",
              "TagKey": "Shift",
              "TagValue": "",
              "MatchKey": "",
              "MatchValue": "",
              "Radius": 1.0,
              "Center": "Volume"
            },
            {
              "Type": "ModifyTags",
              "Event": "TAG_ADDED",
              "Interval": 0.0,
              "Delay": 0.10000000149011612,
              "Operation": "Set",
              "TagKey": "DisplayNumber",
              "TagValue": "6",
              "MatchKey": "ID",
              "MatchValue": "Display4",
              "Radius": 10.0,
              "Center": "Volume"
            },
            {
              "Type": "PlaceBlock",
              "Event": "TAG_ADDED",
              "Interval": 0.0,
              "Delay": 0.10000000149011612,
              "BlockType": "Cloth_Block_Wool_Orange",
              "Position": {
                "X": 0.0,
                "Y": 1.0,
                "Z": -7.0
              },
              "Origin": "VolumeOrigin",
              "ReplaceMode": "Always"
            }
          ],
          "Conditions": [
            {
              "Type": "TagCondition",
              "Event": "TAG_ADDED",
              "Source": "Radius",
              "TagKey": "DisplayNumber",
              "TagValue": "6",
              "MatchKey": "ID",
              "MatchValue": "Display3",
              "Radius": 10.0,
              "Center": "Volume"
            }
          ],
          "RejectionEffects": [
            {
              "Type": "ModifyTags",
              "Event": "TAG_ADDED",
              "Interval": 0.0,
              "Delay": 0.0,
              "Operation": "Remove",
              "TagKey": "Shift",
              "TagValue": "",
              "MatchKey": "",
              "MatchValue": "",
              "Radius": 1.0,
              "Center": "Volume"
            }
          ],
          "Enabled": true,
          "TargetTypes": [
            "Player"
          ],
          "Tags": {
            "Clearable": "1",
            "ID": "ShiftCalc3"
          },
          "KeepLoaded": false,
          "GroupLinkId": "20ecfec7-f1d2-4c1d-a6e1-65726c14fec4",
          "PrefabIndex": 1
        }
      }
    },
    {
      "Components": {
        "Transform": {
          "Position": {
            "X": -2.5,
            "Y": 1.0,
            "Z": 4.0
          },
          "Rotation": {
            "Pitch": 0.0,
            "Yaw": 0.0,
            "Roll": 0.0
          }
        },
        "TriggerVolumeGroup": {
          "GroupLinkId": "1a8f8788-231f-48ca-b648-729d8dcdcac7",
          "TargetTypes": [
            "Player"
          ],
          "Enabled": true,
          "Color": 14708784
        }
      }
    },
    {
      "Components": {
        "Transform": {
          "Position": {
            "X": -2.5,
            "Y": 1.0,
            "Z": 4.5
          },
          "Rotation": {
            "Pitch": 0.0,
            "Yaw": 0.0,
            "Roll": 0.0
          }
        },
        "TriggerVolume": {
          "Shape": {
            "Type": "Box",
            "Min": {
              "X": -0.5,
              "Y": -0.25,
              "Z": -0.5
            },
            "Max": {
              "X": 0.5,
              "Y": 0.25,
              "Z": 0.5
            }
          },
          "Effects": [
            {
              "Type": "ModifyTags",
              "Event": "TAG_ADDED",
              "Interval": 0.0,
              "Delay": 0.0,
              "Operation": "Set",
              "TagKey": "Shift",
              "TagValue": "Empty",
              "MatchKey": "ID",
              "MatchValue": "ShiftCalc",
              "Radius": 15.0,
              "Center": "Volume"
            },
            {
              "Type": "ModifyTags",
              "Event": "TAG_ADDED",
              "Interval": 0.0,
              "Delay": 0.10000000149011612,
              "Operation": "Remove",
              "TagKey": "DisplayNumber",
              "TagValue": "",
              "MatchKey": "",
              "MatchValue": "",
              "Radius": 1.0,
              "Center": "Volume"
            },
            {
              "Type": "ModifyTags",
              "Event": "TAG_ADDED",
              "Interval": 0.0,
              "Delay": 0.10000000149011612,
              "Operation": "Set",
              "TagKey": "DisplayNumber",
              "TagValue": "5",
              "MatchKey": "ID",
              "MatchValue": "Display1",
              "Radius": 10.0,
              "Center": "Volume"
            },
            {
              "Type": "PlaceBlock",
              "Event": "TAG_ADDED",
              "Interval": 0.0,
              "Delay": 0.10000000149011612,
              "BlockType": "Cloth_Block_Wool_Red",
              "Position": {
                "X": 0.0,
                "Y": 1.0,
                "Z": -6.0
              },
              "Origin": "VolumeOrigin",
              "ReplaceMode": "Always"
            }
          ],
          "Conditions": [
            {
              "Type": "TagCondition",
              "Event": "TAG_ADDED",
              "Source": "Self",
              "TagKey": "DisplayNumber",
              "TagValue": "5",
              "MatchKey": "",
              "MatchValue": "",
              "Radius": 1.0,
              "Center": "Volume"
            }
          ],
          "RejectionEffects": [
            {
              "Type": "ModifyTags",
              "Event": "TAG_ADDED",
              "Interval": 0.0,
              "Delay": 0.0,
              "Operation": "Remove",
              "TagKey": "DisplayNumber",
              "TagValue": "",
              "MatchKey": "",
              "MatchValue": "",
              "Radius": 0.0,
              "Center": "Volume"
            }
          ],
          "Enabled": true,
          "TargetTypes": [
            "Player"
          ],
          "Tags": {
            "Clearable": "1",
            "ID": "DisplayCalc"
          },
          "KeepLoaded": false,
          "GroupLinkId": "1a8f8788-231f-48ca-b648-729d8dcdcac7",
          "PrefabIndex": 2
        }
      }
    },
    {
      "Components": {
        "Transform": {
          "Position": {
            "X": -0.5,
            "Y": 1.0,
            "Z": 4.0
          },
          "Rotation": {
            "Pitch": 0.0,
            "Yaw": 0.0,
            "Roll": 0.0
          }
        },
        "TriggerVolumeGroup": {
          "GroupLinkId": "c7f77157-d4b0-49d8-af7d-90c94344814a",
          "TargetTypes": [
            "Player"
          ],
          "Enabled": true,
          "Color": 14708784
        }
      }
    },
    {
      "Components": {
        "Transform": {
          "Position": {
            "X": -0.5,
            "Y": 1.0,
            "Z": 5.5
          },
          "Rotation": {
            "Pitch": 0.0,
            "Yaw": 0.0,
            "Roll": 0.0
          }
        },
        "TriggerVolume": {
          "Shape": {
            "Type": "Box",
            "Min": {
              "X": -0.5,
              "Y": -0.25,
              "Z": -0.5
            },
            "Max": {
              "X": 0.5,
              "Y": 0.25,
              "Z": 0.5
            }
          },
          "Effects": [
            {
              "Type": "ModifyTags",
              "Event": "TAG_ADDED",
              "Interval": 0.0,
              "Delay": 0.0,
              "Operation": "Set",
              "TagKey": "Shift",
              "TagValue": "Empty",
              "MatchKey": "ID",
              "MatchValue": "ShiftCalc3",
              "Radius": 20.0,
              "Center": "Volume"
            },
            {
              "Type": "ModifyTags",
              "Event": "TAG_ADDED",
              "Interval": 0.0,
              "Delay": 0.0,
              "Operation": "Remove",
              "TagKey": "Shift",
              "TagValue": "",
              "MatchKey": "",
              "MatchValue": "",
              "Radius": 1.0,
              "Center": "Volume"
            },
            {
              "Type": "ModifyTags",
              "Event": "TAG_ADDED",
              "Interval": 0.0,
              "Delay": 0.10000000149011612,
              "Operation": "Set",
              "TagKey": "DisplayNumber",
              "TagValue": "6",
              "MatchKey": "ID",
              "MatchValue": "Display3",
              "Radius": 10.0,
              "Center": "Volume"
            },
            {
              "Type": "PlaceBlock",
              "Event": "TAG_ADDED",
              "Interval": 0.0,
              "Delay": 0.10000000149011612,
              "BlockType": "Cloth_Block_Wool_Orange",
              "Position": {
                "X": 0.0,
                "Y": 1.0,
                "Z": -7.0
              },
              "Origin": "VolumeOrigin",
              "ReplaceMode": "Always"
            }
          ],
          "Conditions": [
            {
              "Type": "TagCondition",
              "Event": "TAG_ADDED",
              "Source": "Radius",
              "TagKey": "DisplayNumber",
              "TagValue": "6",
              "MatchKey": "ID",
              "MatchValue": "Display2",
              "Radius": 10.0,
              "Center": "Volume"
            }
          ],
          "RejectionEffects": [
            {
              "Type": "ModifyTags",
              "Event": "TAG_ADDED",
              "Interval": 0.0,
              "Delay": 0.0,
              "Operation": "Remove",
              "TagKey": "Shift",
              "TagValue": "",
              "MatchKey": "",
              "MatchValue": "",
              "Radius": 1.0,
              "Center": "Volume"
            }
          ],
          "Enabled": true,
          "TargetTypes": [
            "Player"
          ],
          "Tags": {
            "Clearable": "1",
            "ID": "ShiftCalc2"
          },
          "KeepLoaded": false,
          "ActivationDelay": 0.10000000149011612,
          "GroupLinkId": "c7f77157-d4b0-49d8-af7d-90c94344814a",
          "PrefabIndex": 3
        }
      }
    },
    {
      "Components": {
        "Transform": {
          "Position": {
            "X": 2.5,
            "Y": 1.0,
            "Z": 4.0
          },
          "Rotation": {
            "Pitch": 0.0,
            "Yaw": 0.0,
            "Roll": 0.0
          }
        },
        "TriggerVolumeGroup": {
          "GroupLinkId": "06ea7e6f-986e-434b-91f4-c1dbc89fd9ee",
          "TargetTypes": [
            "Player"
          ],
          "Enabled": true,
          "Color": 14708784
        }
      }
    },
    {
      "Components": {
        "Transform": {
          "Position": {
            "X": 2.5,
            "Y": 1.0,
            "Z": -0.5
          },
          "Rotation": {
            "Pitch": 0.0,
            "Yaw": 0.0,
            "Roll": 0.0
          }
        },
        "TriggerVolume": {
          "Shape": {
            "Type": "Box",
            "Min": {
              "X": -0.5,
              "Y": -0.25,
              "Z": -0.5
            },
            "Max": {
              "X": 0.5,
              "Y": 0.25,
              "Z": 0.5
            }
          },
          "Effects": [
            {
              "Type": "ModifyTags",
              "Event": "TAG_ADDED",
              "Interval": 0.0,
              "Delay": 0.0,
              "Operation": "Set",
              "TagKey": "Shift",
              "TagValue": "Empty",
              "MatchKey": "ID",
              "MatchValue": "ShiftCalc6",
              "Radius": 20.0,
              "Center": "Volume"
            },
            {
              "Type": "ModifyTags",
              "Event": "TAG_ADDED",
              "Interval": 0.0,
              "Delay": 0.10000000149011612,
              "Operation": "Remove",
              "TagKey": "Shift",
              "TagValue": "",
              "MatchKey": "",
              "MatchValue": "",
              "Radius": 1.0,
              "Center": "Volume"
            },
            {
              "Type": "ModifyTags",
              "Event": "TAG_ADDED",
              "Interval": 0.0,
              "Delay": 0.10000000149011612,
              "Operation": "Set",
              "TagKey": "DisplayNumber",
              "TagValue": "0",
              "MatchKey": "ID",
              "MatchValue": "Display6",
              "Radius": 15.0,
              "Center": "Volume"
            },
            {
              "Type": "PlaceBlock",
              "Event": "TAG_ADDED",
              "Interval": 0.0,
              "Delay": 0.10000000149011612,
              "BlockType": "Cloth_Block_Wool_White",
              "Position": {
                "X": 0.0,
                "Y": 1.0,
                "Z": -1.0
              },
              "Origin": "VolumeOrigin",
              "ReplaceMode": "Always"
            }
          ],
          "Conditions": [
            {
              "Type": "TagCondition",
              "Event": "TAG_ADDED",
              "Source": "Radius",
              "TagKey": "DisplayNumber",
              "TagValue": "0",
              "MatchKey": "ID",
              "MatchValue": "Display5",
              "Radius": 15.0,
              "Center": "Volume"
            }
          ],
          "RejectionEffects": [
            {
              "Type": "ModifyTags",
              "Event": "TAG_ADDED",
              "Interval": 0.0,
              "Delay": 0.0,
              "Operation": "Remove",
              "TagKey": "Shift",
              "TagValue": "",
              "MatchKey": "",
              "MatchValue": "",
              "Radius": 1.0,
              "Center": "Volume"
            }
          ],
          "Enabled": true,
          "TargetTypes": [
            "Player"
          ],
          "Tags": {
            "ID": "ShiftCalc5"
          },
          "KeepLoaded": false,
          "GroupLinkId": "06ea7e6f-986e-434b-91f4-c1dbc89fd9ee",
          "PrefabIndex": 4
        }
      }
    },
    {
      "Components": {
        "Transform": {
          "Position": {
            "X": -0.5,
            "Y": 1.0,
            "Z": -0.5
          },
          "Rotation": {
            "Pitch": 0.0,
            "Yaw": 0.0,
            "Roll": 0.0
          }
        },
        "TriggerVolume": {
          "Shape": {
            "Type": "Box",
            "Min": {
              "X": -0.5,
              "Y": -0.25,
              "Z": -0.5
            },
            "Max": {
              "X": 0.5,
              "Y": 0.25,
              "Z": 0.5
            }
          },
          "Effects": [
            {
              "Type": "ModifyTags",
              "Event": "TAG_ADDED",
              "Interval": 0.0,
              "Delay": 0.0,
              "Operation": "Set",
              "TagKey": "Shift",
              "TagValue": "Empty",
              "MatchKey": "ID",
              "MatchValue": "ShiftCalc3",
              "Radius": 20.0,
              "Center": "Volume"
            },
            {
              "Type": "ModifyTags",
              "Event": "TAG_ADDED",
              "Interval": 0.0,
              "Delay": 0.10000000149011612,
              "Operation": "Remove",
              "TagKey": "Shift",
              "TagValue": "",
              "MatchKey": "",
              "MatchValue": "",
              "Radius": 1.0,
              "Center": "Volume"
            },
            {
              "Type": "ModifyTags",
              "Event": "TAG_ADDED",
              "Interval": 0.0,
              "Delay": 0.10000000149011612,
              "Operation": "Set",
              "TagKey": "DisplayNumber",
              "TagValue": "0",
              "MatchKey": "ID",
              "MatchValue": "Display3",
              "Radius": 15.0,
              "Center": "Volume"
            },
            {
              "Type": "PlaceBlock",
              "Event": "TAG_ADDED",
              "Interval": 0.0,
              "Delay": 0.10000000149011612,
              "BlockType": "Cloth_Block_Wool_White",
              "Position": {
                "X": 0.0,
                "Y": 1.0,
                "Z": -1.0
              },
              "Origin": "VolumeOrigin",
              "ReplaceMode": "Always"
            }
          ],
          "Conditions": [
            {
              "Type": "TagCondition",
              "Event": "TAG_ADDED",
              "Source": "Radius",
              "TagKey": "DisplayNumber",
              "TagValue": "0",
              "MatchKey": "ID",
              "MatchValue": "Display2",
              "Radius": 15.0,
              "Center": "Volume"
            }
          ],
          "RejectionEffects": [
            {
              "Type": "ModifyTags",
              "Event": "TAG_ADDED",
              "Interval": 0.0,
              "Delay": 0.0,
              "Operation": "Remove",
              "TagKey": "Shift",
              "TagValue": "",
              "MatchKey": "",
              "MatchValue": "",
              "Radius": 1.0,
              "Center": "Volume"
            }
          ],
          "Enabled": true,
          "TargetTypes": [
            "Player"
          ],
          "Tags": {
            "Clearable": "1",
            "ID": "ShiftCalc2"
          },
          "KeepLoaded": false,
          "GroupLinkId": "c7f77157-d4b0-49d8-af7d-90c94344814a",
          "PrefabIndex": 5
        }
      }
    },
    {
      "Components": {
        "Transform": {
          "Position": {
            "X": -1.5,
            "Y": 1.0,
            "Z": 4.0
          },
          "Rotation": {
            "Pitch": 0.0,
            "Yaw": 0.0,
            "Roll": 0.0
          }
        },
        "TriggerVolumeGroup": {
          "GroupLinkId": "eedab82c-8e4a-4d28-a54b-8a0d818085f7",
          "TargetTypes": [
            "Player"
          ],
          "Enabled": true,
          "Color": 4239424
        }
      }
    },
    {
      "Components": {
        "Transform": {
          "Position": {
            "X": -1.5,
            "Y": 1.0,
            "Z": 5.5
          },
          "Rotation": {
            "Pitch": 0.0,
            "Yaw": 0.0,
            "Roll": 0.0
          }
        },
        "TriggerVolume": {
          "Shape": {
            "Type": "Box",
            "Min": {
              "X": -0.5,
              "Y": -0.25,
              "Z": -0.5
            },
            "Max": {
              "X": 0.5,
              "Y": 0.25,
              "Z": 0.5
            }
          },
          "Effects": [
            {
              "Type": "ModifyTags",
              "Event": "TAG_ADDED",
              "Interval": 0.0,
              "Delay": 0.0,
              "Operation": "Set",
              "TagKey": "Shift",
              "TagValue": "Empty",
              "MatchKey": "ID",
              "MatchValue": "ShiftCalc2",
              "Radius": 20.0,
              "Center": "Volume"
            },
            {
              "Type": "ModifyTags",
              "Event": "TAG_ADDED",
              "Interval": 0.0,
              "Delay": 0.0,
              "Operation": "Remove",
              "TagKey": "Shift",
              "TagValue": "",
              "MatchKey": "",
              "MatchValue": "",
              "Radius": 1.0,
              "Center": "Volume"
            },
            {
              "Type": "ModifyTags",
              "Event": "TAG_ADDED",
              "Interval": 0.0,
              "Delay": 0.10000000149011612,
              "Operation": "Set",
              "TagKey": "DisplayNumber",
              "TagValue": "6",
              "MatchKey": "ID",
              "MatchValue": "Display2",
              "Radius": 10.0,
              "Center": "Volume"
            },
            {
              "Type": "PlaceBlock",
              "Event": "TAG_ADDED",
              "Interval": 0.0,
              "Delay": 0.10000000149011612,
              "BlockType": "Cloth_Block_Wool_Orange",
              "Position": {
                "X": 0.0,
                "Y": 1.0,
                "Z": -7.0
              },
              "Origin": "VolumeOrigin",
              "ReplaceMode": "Always"
            }
          ],
          "Conditions": [
            {
              "Type": "TagCondition",
              "Event": "TAG_ADDED",
              "Source": "Radius",
              "TagKey": "DisplayNumber",
              "TagValue": "6",
              "MatchKey": "ID",
              "MatchValue": "Display1",
              "Radius": 10.0,
              "Center": "Volume"
            }
          ],
          "RejectionEffects": [
            {
              "Type": "ModifyTags",
              "Event": "TAG_ADDED",
              "Interval": 0.0,
              "Delay": 0.0,
              "Operation": "Remove",
              "TagKey": "Shift",
              "TagValue": "",
              "MatchKey": "",
              "MatchValue": "",
              "Radius": 1.0,
              "Center": "Volume"
            }
          ],
          "Enabled": true,
          "TargetTypes": [
            "Player"
          ],
          "Tags": {
            "Clearable": "1",
            "ID": "ShiftCalc"
          },
          "KeepLoaded": false,
          "GroupLinkId": "eedab82c-8e4a-4d28-a54b-8a0d818085f7",
          "PrefabIndex": 6
        }
      }
    },
    {
      "Components": {
        "Transform": {
          "Position": {
            "X": 0.5,
            "Y": 1.0,
            "Z": -0.5
          },
          "Rotation": {
            "Pitch": 0.0,
            "Yaw": 0.0,
            "Roll": 0.0
          }
        },
        "TriggerVolume": {
          "Shape": {
            "Type": "Box",
            "Min": {
              "X": -0.5,
              "Y": -0.25,
              "Z": -0.5
            },
            "Max": {
              "X": 0.5,
              "Y": 0.25,
              "Z": 0.5
            }
          },
          "Effects": [
            {
              "Type": "ModifyTags",
              "Event": "TAG_ADDED",
              "Interval": 0.0,
              "Delay": 0.0,
              "Operation": "Set",
              "TagKey": "Shift",
              "TagValue": "Empty",
              "MatchKey": "ID",
              "MatchValue": "ShiftCalc4",
              "Radius": 20.0,
              "Center": "Volume"
            },
            {
              "Type": "ModifyTags",
              "Event": "TAG_ADDED",
              "Interval": 0.0,
              "Delay": 0.10000000149011612,
              "Operation": "Remove",
              "TagKey": "Shift",
              "TagValue": "",
              "MatchKey": "",
              "MatchValue": "",
              "Radius": 1.0,
              "Center": "Volume"
            },
            {
              "Type": "ModifyTags",
              "Event": "TAG_ADDED",
              "Interval": 0.0,
              "Delay": 0.10000000149011612,
              "Operation": "Set",
              "TagKey": "DisplayNumber",
              "TagValue": "0",
              "MatchKey": "ID",
              "MatchValue": "Display4",
              "Radius": 15.0,
              "Center": "Volume"
            },
            {
              "Type": "PlaceBlock",
              "Event": "TAG_ADDED",
              "Interval": 0.0,
              "Delay": 0.10000000149011612,
              "BlockType": "Cloth_Block_Wool_White",
              "Position": {
                "X": 0.0,
                "Y": 1.0,
                "Z": -1.0
              },
              "Origin": "VolumeOrigin",
              "ReplaceMode": "Always"
            }
          ],
          "Conditions": [
            {
              "Type": "TagCondition",
              "Event": "TAG_ADDED",
              "Source": "Radius",
              "TagKey": "DisplayNumber",
              "TagValue": "0",
              "MatchKey": "ID",
              "MatchValue": "Display3",
              "Radius": 15.0,
              "Center": "Volume"
            }
          ],
          "RejectionEffects": [
            {
              "Type": "ModifyTags",
              "Event": "TAG_ADDED",
              "Interval": 0.0,
              "Delay": 0.0,
              "Operation": "Remove",
              "TagKey": "Shift",
              "TagValue": "",
              "MatchKey": "",
              "MatchValue": "",
              "Radius": 1.0,
              "Center": "Volume"
            }
          ],
          "Enabled": true,
          "TargetTypes": [
            "Player"
          ],
          "Tags": {
            "Clearable": "1",
            "ID": "ShiftCalc3"
          },
          "KeepLoaded": false,
          "GroupLinkId": "20ecfec7-f1d2-4c1d-a6e1-65726c14fec4",
          "PrefabIndex": 7
        }
      }
    },
    {
      "Components": {
        "Transform": {
          "Position": {
            "X": 4.5,
            "Y": 1.0,
            "Z": 4.0
          },
          "Rotation": {
            "Pitch": 0.0,
            "Yaw": 0.0,
            "Roll": 0.0
          }
        },
        "TriggerVolumeGroup": {
          "GroupLinkId": "c31351a9-5e6c-4ce3-b281-5bd22891efcd",
          "TargetTypes": [
            "Player"
          ],
          "Enabled": true,
          "Color": 14708784
        }
      }
    },
    {
      "Components": {
        "Transform": {
          "Position": {
            "X": 4.5,
            "Y": 1.0,
            "Z": 5.5
          },
          "Rotation": {
            "Pitch": 0.0,
            "Yaw": 0.0,
            "Roll": 0.0
          }
        },
        "TriggerVolume": {
          "Shape": {
            "Type": "Box",
            "Min": {
              "X": -0.5,
              "Y": -0.25,
              "Z": -0.5
            },
            "Max": {
              "X": 0.5,
              "Y": 0.25,
              "Z": 0.5
            }
          },
          "Effects": [
            {
              "Type": "ModifyTags",
              "Event": "TAG_ADDED",
              "Interval": 0.0,
              "Delay": 0.0,
              "Operation": "Set",
              "TagKey": "Shift",
              "TagValue": "Empty",
              "MatchKey": "ID",
              "MatchValue": "ShiftCalc8",
              "Radius": 20.0,
              "Center": "Volume"
            },
            {
              "Type": "ModifyTags",
              "Event": "TAG_ADDED",
              "Interval": 0.0,
              "Delay": 0.0,
              "Operation": "Remove",
              "TagKey": "Shift",
              "TagValue": "",
              "MatchKey": "",
              "MatchValue": "",
              "Radius": 1.0,
              "Center": "Volume"
            },
            {
              "Type": "ModifyTags",
              "Event": "TAG_ADDED",
              "Interval": 0.0,
              "Delay": 0.10000000149011612,
              "Operation": "Set",
              "TagKey": "DisplayNumber",
              "TagValue": "6",
              "MatchKey": "ID",
              "MatchValue": "Display8",
              "Radius": 10.0,
              "Center": "Volume"
            },
            {
              "Type": "PlaceBlock",
              "Event": "TAG_ADDED",
              "Interval": 0.0,
              "Delay": 0.10000000149011612,
              "BlockType": "Cloth_Block_Wool_Orange",
              "Position": {
                "X": 0.0,
                "Y": 1.0,
                "Z": -7.0
              },
              "Origin": "VolumeOrigin",
              "ReplaceMode": "Always"
            }
          ],
          "Conditions": [
            {
              "Type": "TagCondition",
              "Event": "TAG_ADDED",
              "Source": "Radius",
              "TagKey": "DisplayNumber",
              "TagValue": "6",
              "MatchKey": "ID",
              "MatchValue": "Display7",
              "Radius": 10.0,
              "Center": "Volume"
            }
          ],
          "RejectionEffects": [
            {
              "Type": "ModifyTags",
              "Event": "TAG_ADDED",
              "Interval": 0.0,
              "Delay": 0.0,
              "Operation": "Remove",
              "TagKey": "Shift",
              "TagValue": "",
              "MatchKey": "",
              "MatchValue": "",
              "Radius": 1.0,
              "Center": "Volume"
            }
          ],
          "Enabled": true,
          "TargetTypes": [
            "Player"
          ],
          "Tags": {
            "Clearable": "1",
            "ID": "ShiftCalc7"
          },
          "KeepLoaded": false,
          "GroupLinkId": "c31351a9-5e6c-4ce3-b281-5bd22891efcd",
          "PrefabIndex": 8
        }
      }
    },
    {
      "Components": {
        "Transform": {
          "Position": {
            "X": 3.5,
            "Y": 1.0,
            "Z": 4.0
          },
          "Rotation": {
            "Pitch": 0.0,
            "Yaw": 0.0,
            "Roll": 0.0
          }
        },
        "TriggerVolumeGroup": {
          "GroupLinkId": "99636112-6f15-447a-8003-d74054db5a0c",
          "TargetTypes": [
            "Player"
          ],
          "Enabled": true,
          "Color": 4239424
        }
      }
    },
    {
      "Components": {
        "Transform": {
          "Position": {
            "X": 3.5,
            "Y": 1.0,
            "Z": 5.5
          },
          "Rotation": {
            "Pitch": 0.0,
            "Yaw": 0.0,
            "Roll": 0.0
          }
        },
        "TriggerVolume": {
          "Shape": {
            "Type": "Box",
            "Min": {
              "X": -0.5,
              "Y": -0.25,
              "Z": -0.5
            },
            "Max": {
              "X": 0.5,
              "Y": 0.25,
              "Z": 0.5
            }
          },
          "Effects": [
            {
              "Type": "ModifyTags",
              "Event": "TAG_ADDED",
              "Interval": 0.0,
              "Delay": 0.0,
              "Operation": "Set",
              "TagKey": "Shift",
              "TagValue": "Empty",
              "MatchKey": "ID",
              "MatchValue": "ShiftCalc7",
              "Radius": 20.0,
              "Center": "Volume"
            },
            {
              "Type": "ModifyTags",
              "Event": "TAG_ADDED",
              "Interval": 0.0,
              "Delay": 0.0,
              "Operation": "Remove",
              "TagKey": "Shift",
              "TagValue": "",
              "MatchKey": "",
              "MatchValue": "",
              "Radius": 1.0,
              "Center": "Volume"
            },
            {
              "Type": "ModifyTags",
              "Event": "TAG_ADDED",
              "Interval": 0.0,
              "Delay": 0.20000000298023224,
              "Operation": "Set",
              "TagKey": "DisplayNumber",
              "TagValue": "6",
              "MatchKey": "ID",
              "MatchValue": "Display7",
              "Radius": 10.0,
              "Center": "Volume"
            },
            {
              "Type": "PlaceBlock",
              "Event": "TAG_ADDED",
              "Interval": 0.0,
              "Delay": 0.10000000149011612,
              "BlockType": "Cloth_Block_Wool_Orange",
              "Position": {
                "X": 0.0,
                "Y": 1.0,
                "Z": -7.0
              },
              "Origin": "VolumeOrigin",
              "ReplaceMode": "Always"
            }
          ],
          "Conditions": [
            {
              "Type": "TagCondition",
              "Event": "TAG_ADDED",
              "Source": "Radius",
              "TagKey": "DisplayNumber",
              "TagValue": "6",
              "MatchKey": "ID",
              "MatchValue": "Display6",
              "Radius": 10.0,
              "Center": "Volume"
            }
          ],
          "RejectionEffects": [
            {
              "Type": "ModifyTags",
              "Event": "TAG_ADDED",
              "Interval": 0.0,
              "Delay": 0.0,
              "Operation": "Remove",
              "TagKey": "Shift",
              "TagValue": "",
              "MatchKey": "",
              "MatchValue": "",
              "Radius": 1.0,
              "Center": "Volume"
            }
          ],
          "Enabled": true,
          "TargetTypes": [
            "Player"
          ],
          "Tags": {
            "Clearable": "1",
            "ID": "ShiftCalc6"
          },
          "KeepLoaded": false,
          "GroupLinkId": "99636112-6f15-447a-8003-d74054db5a0c",
          "PrefabIndex": 9
        }
      }
    },
    {
      "Components": {
        "Transform": {
          "Position": {
            "X": 2.5,
            "Y": 1.0,
            "Z": 5.5
          },
          "Rotation": {
            "Pitch": 0.0,
            "Yaw": 0.0,
            "Roll": 0.0
          }
        },
        "TriggerVolume": {
          "Shape": {
            "Type": "Box",
            "Min": {
              "X": -0.5,
              "Y": -0.25,
              "Z": -0.5
            },
            "Max": {
              "X": 0.5,
              "Y": 0.25,
              "Z": 0.5
            }
          },
          "Effects": [
            {
              "Type": "ModifyTags",
              "Event": "TAG_ADDED",
              "Interval": 0.0,
              "Delay": 0.0,
              "Operation": "Set",
              "TagKey": "Shift",
              "TagValue": "Empty",
              "MatchKey": "ID",
              "MatchValue": "ShiftCalc6",
              "Radius": 20.0,
              "Center": "Volume"
            },
            {
              "Type": "ModifyTags",
              "Event": "TAG_ADDED",
              "Interval": 0.0,
              "Delay": 0.10000000149011612,
              "Operation": "Remove",
              "TagKey": "Shift",
              "TagValue": "",
              "MatchKey": "",
              "MatchValue": "",
              "Radius": 1.0,
              "Center": "Volume"
            },
            {
              "Type": "ModifyTags",
              "Event": "TAG_ADDED",
              "Interval": 0.0,
              "Delay": 0.10000000149011612,
              "Operation": "Set",
              "TagKey": "DisplayNumber",
              "TagValue": "6",
              "MatchKey": "ID",
              "MatchValue": "Display6",
              "Radius": 10.0,
              "Center": "Volume"
            },
            {
              "Type": "PlaceBlock",
              "Event": "TAG_ADDED",
              "Interval": 0.0,
              "Delay": 0.10000000149011612,
              "BlockType": "Cloth_Block_Wool_Orange",
              "Position": {
                "X": 0.0,
                "Y": 1.0,
                "Z": -7.0
              },
              "Origin": "VolumeOrigin",
              "ReplaceMode": "Always"
            }
          ],
          "Conditions": [
            {
              "Type": "TagCondition",
              "Event": "TAG_ADDED",
              "Source": "Radius",
              "TagKey": "DisplayNumber",
              "TagValue": "6",
              "MatchKey": "ID",
              "MatchValue": "Display5",
              "Radius": 10.0,
              "Center": "Volume"
            }
          ],
          "RejectionEffects": [
            {
              "Type": "ModifyTags",
              "Event": "TAG_ADDED",
              "Interval": 0.0,
              "Delay": 0.0,
              "Operation": "Remove",
              "TagKey": "Shift",
              "TagValue": "",
              "MatchKey": "",
              "MatchValue": "",
              "Radius": 1.0,
              "Center": "Volume"
            }
          ],
          "Enabled": true,
          "TargetTypes": [
            "Player"
          ],
          "Tags": {
            "ID": "ShiftCalc5"
          },
          "KeepLoaded": false,
          "GroupLinkId": "06ea7e6f-986e-434b-91f4-c1dbc89fd9ee",
          "PrefabIndex": 10
        }
      }
    },
    {
      "Components": {
        "Transform": {
          "Position": {
            "X": 3.5,
            "Y": 1.0,
            "Z": -0.5
          },
          "Rotation": {
            "Pitch": 0.0,
            "Yaw": 0.0,
            "Roll": 0.0
          }
        },
        "TriggerVolume": {
          "Shape": {
            "Type": "Box",
            "Min": {
              "X": -0.5,
              "Y": -0.25,
              "Z": -0.5
            },
            "Max": {
              "X": 0.5,
              "Y": 0.25,
              "Z": 0.5
            }
          },
          "Effects": [
            {
              "Type": "ModifyTags",
              "Event": "TAG_ADDED",
              "Interval": 0.0,
              "Delay": 0.0,
              "Operation": "Set",
              "TagKey": "Shift",
              "TagValue": "Empty",
              "MatchKey": "ID",
              "MatchValue": "ShiftCalc7",
              "Radius": 20.0,
              "Center": "Volume"
            },
            {
              "Type": "ModifyTags",
              "Event": "TAG_ADDED",
              "Interval": 0.0,
              "Delay": 0.0,
              "Operation": "Remove",
              "TagKey": "Shift",
              "TagValue": "",
              "MatchKey": "",
              "MatchValue": "",
              "Radius": 1.0,
              "Center": "Volume"
            },
            {
              "Type": "ModifyTags",
              "Event": "TAG_ADDED",
              "Interval": 0.0,
              "Delay": 0.20000000298023224,
              "Operation": "Set",
              "TagKey": "DisplayNumber",
              "TagValue": "0",
              "MatchKey": "ID",
              "MatchValue": "Display7",
              "Radius": 15.0,
              "Center": "Volume"
            },
            {
              "Type": "PlaceBlock",
              "Event": "TAG_ADDED",
              "Interval": 0.0,
              "Delay": 0.10000000149011612,
              "BlockType": "Cloth_Block_Wool_White",
              "Position": {
                "X": 0.0,
                "Y": 1.0,
                "Z": -1.0
              },
              "Origin": "VolumeOrigin",
              "ReplaceMode": "Always"
            }
          ],
          "Conditions": [
            {
              "Type": "TagCondition",
              "Event": "TAG_ADDED",
              "Source": "Radius",
              "TagKey": "DisplayNumber",
              "TagValue": "0",
              "MatchKey": "ID",
              "MatchValue": "Display6",
              "Radius": 15.0,
              "Center": "Volume"
            }
          ],
          "RejectionEffects": [
            {
              "Type": "ModifyTags",
              "Event": "TAG_ADDED",
              "Interval": 0.0,
              "Delay": 0.0,
              "Operation": "Remove",
              "TagKey": "Shift",
              "TagValue": "",
              "MatchKey": "",
              "MatchValue": "",
              "Radius": 1.0,
              "Center": "Volume"
            }
          ],
          "Enabled": true,
          "TargetTypes": [
            "Player"
          ],
          "Tags": {
            "Clearable": "1",
            "ID": "ShiftCalc6"
          },
          "KeepLoaded": false,
          "GroupLinkId": "99636112-6f15-447a-8003-d74054db5a0c",
          "PrefabIndex": 11
        }
      }
    },
    {
      "Components": {
        "Transform": {
          "Position": {
            "X": 1.5,
            "Y": 1.0,
            "Z": 5.5
          },
          "Rotation": {
            "Pitch": 0.0,
            "Yaw": 0.0,
            "Roll": 0.0
          }
        },
        "TriggerVolume": {
          "Shape": {
            "Type": "Box",
            "Min": {
              "X": -0.5,
              "Y": -0.25,
              "Z": -0.5
            },
            "Max": {
              "X": 0.5,
              "Y": 0.25,
              "Z": 0.5
            }
          },
          "Effects": [
            {
              "Type": "ModifyTags",
              "Event": "TAG_ADDED",
              "Interval": 0.0,
              "Delay": 0.0,
              "Operation": "Set",
              "TagKey": "Shift",
              "TagValue": "Empty",
              "MatchKey": "ID",
              "MatchValue": "ShiftCalc5",
              "Radius": 20.0,
              "Center": "Volume"
            },
            {
              "Type": "ModifyTags",
              "Event": "TAG_ADDED",
              "Interval": 0.0,
              "Delay": 0.10000000149011612,
              "Operation": "Remove",
              "TagKey": "Shift",
              "TagValue": "",
              "MatchKey": "",
              "MatchValue": "",
              "Radius": 1.0,
              "Center": "Volume"
            },
            {
              "Type": "ModifyTags",
              "Event": "TAG_ADDED",
              "Interval": 0.0,
              "Delay": 0.10000000149011612,
              "Operation": "Set",
              "TagKey": "DisplayNumber",
              "TagValue": "6",
              "MatchKey": "ID",
              "MatchValue": "Display5",
              "Radius": 10.0,
              "Center": "Volume"
            },
            {
              "Type": "PlaceBlock",
              "Event": "TAG_ADDED",
              "Interval": 0.0,
              "Delay": 0.10000000149011612,
              "BlockType": "Cloth_Block_Wool_Orange",
              "Position": {
                "X": 0.0,
                "Y": 1.0,
                "Z": -7.0
              },
              "Origin": "VolumeOrigin",
              "ReplaceMode": "Always"
            }
          ],
          "Conditions": [
            {
              "Type": "TagCondition",
              "Event": "TAG_ADDED",
              "Source": "Radius",
              "TagKey": "DisplayNumber",
              "TagValue": "6",
              "MatchKey": "ID",
              "MatchValue": "Display4",
              "Radius": 10.0,
              "Center": "Volume"
            }
          ],
          "RejectionEffects": [
            {
              "Type": "ModifyTags",
              "Event": "TAG_ADDED",
              "Interval": 0.0,
              "Delay": 0.0,
              "Operation": "Remove",
              "TagKey": "Shift",
              "TagValue": "",
              "MatchKey": "",
              "MatchValue": "",
              "Radius": 1.0,
              "Center": "Volume"
            }
          ],
          "Enabled": true,
          "TargetTypes": [
            "Player"
          ],
          "Tags": {
            "ID": "ShiftCalc4"
          },
          "KeepLoaded": false,
          "GroupLinkId": "cdd9a5b8-9518-4155-ba8a-d8e6bd1449b1",
          "PrefabIndex": 12
        }
      }
    },
    {
      "Components": {
        "Transform": {
          "Position": {
            "X": 4.5,
            "Y": 1.0,
            "Z": -0.5
          },
          "Rotation": {
            "Pitch": 0.0,
            "Yaw": 0.0,
            "Roll": 0.0
          }
        },
        "TriggerVolume": {
          "Shape": {
            "Type": "Box",
            "Min": {
              "X": -0.5,
              "Y": -0.25,
              "Z": -0.5
            },
            "Max": {
              "X": 0.5,
              "Y": 0.25,
              "Z": 0.5
            }
          },
          "Effects": [
            {
              "Type": "ModifyTags",
              "Event": "TAG_ADDED",
              "Interval": 0.0,
              "Delay": 0.0,
              "Operation": "Set",
              "TagKey": "Shift",
              "TagValue": "Empty",
              "MatchKey": "ID",
              "MatchValue": "ShiftCalc8",
              "Radius": 20.0,
              "Center": "Volume"
            },
            {
              "Type": "ModifyTags",
              "Event": "TAG_ADDED",
              "Interval": 0.0,
              "Delay": 0.0,
              "Operation": "Remove",
              "TagKey": "Shift",
              "TagValue": "",
              "MatchKey": "",
              "MatchValue": "",
              "Radius": 1.0,
              "Center": "Volume"
            },
            {
              "Type": "ModifyTags",
              "Event": "TAG_ADDED",
              "Interval": 0.0,
              "Delay": 0.10000000149011612,
              "Operation": "Set",
              "TagKey": "DisplayNumber",
              "TagValue": "0",
              "MatchKey": "ID",
              "MatchValue": "Display8",
              "Radius": 15.0,
              "Center": "Volume"
            },
            {
              "Type": "PlaceBlock",
              "Event": "TAG_ADDED",
              "Interval": 0.0,
              "Delay": 0.10000000149011612,
              "BlockType": "Cloth_Block_Wool_White",
              "Position": {
                "X": 0.0,
                "Y": 1.0,
                "Z": -1.0
              },
              "Origin": "VolumeOrigin",
              "ReplaceMode": "Always"
            }
          ],
          "Conditions": [
            {
              "Type": "TagCondition",
              "Event": "TAG_ADDED",
              "Source": "Radius",
              "TagKey": "DisplayNumber",
              "TagValue": "0",
              "MatchKey": "ID",
              "MatchValue": "Display7",
              "Radius": 15.0,
              "Center": "Volume"
            }
          ],
          "RejectionEffects": [
            {
              "Type": "ModifyTags",
              "Event": "TAG_ADDED",
              "Interval": 0.0,
              "Delay": 0.0,
              "Operation": "Remove",
              "TagKey": "Shift",
              "TagValue": "",
              "MatchKey": "",
              "MatchValue": "",
              "Radius": 1.0,
              "Center": "Volume"
            }
          ],
          "Enabled": true,
          "TargetTypes": [
            "Player"
          ],
          "Tags": {
            "Clearable": "1",
            "ID": "ShiftCalc7"
          },
          "KeepLoaded": false,
          "GroupLinkId": "c31351a9-5e6c-4ce3-b281-5bd22891efcd",
          "PrefabIndex": 13
        }
      }
    },
    {
      "Components": {
        "Transform": {
          "Position": {
            "X": 1.0,
            "Y": 2.5,
            "Z": -1.5
          },
          "Rotation": {
            "Pitch": 0.0,
            "Yaw": 0.0,
            "Roll": 0.0
          }
        },
        "TriggerVolumeGroup": {
          "GroupLinkId": "ab62ddef-cc27-46fe-806f-08f0ac74c073",
          "TargetTypes": [
            "Player"
          ],
          "Enabled": true,
          "Color": 13656208
        }
      }
    },
    {
      "Components": {
        "Transform": {
          "Position": {
            "X": -1.5,
            "Y": 2.5,
            "Z": -1.5
          },
          "Rotation": {
            "Pitch": 0.0,
            "Yaw": 0.0,
            "Roll": 0.0
          }
        },
        "TriggerVolume": {
          "Shape": {
            "Type": "Box",
            "Min": {
              "X": -0.5,
              "Y": -0.5,
              "Z": -0.5
            },
            "Max": {
              "X": 0.5,
              "Y": 0.5,
              "Z": 0.5
            }
          },
          "Effects": [
            {
              "Type": "PlaceBlock",
              "Event": "TAG_ADDED",
              "Interval": 0.0,
              "Delay": 0.0,
              "BlockType": "Soil_Clay_Smooth_Black",
              "Position": {
                "X": 0.0,
                "Y": 0.0,
                "Z": 0.0
              },
              "Origin": "VolumeOrigin",
              "ReplaceMode": "Always"
            },
            {
              "Type": "ModifyTags",
              "Event": "TAG_ADDED",
              "Interval": 0.0,
              "Delay": 0.0,
              "Operation": "Remove",
              "TagKey": "Clearable",
              "TagValue": "1",
              "MatchKey": "",
              "MatchValue": "",
              "Radius": 20.0,
              "Center": "Volume"
            },
            {
              "Type": "ModifyTags",
              "Event": "TAG_ADDED",
              "Interval": 0.0,
              "Delay": 0.0,
              "Operation": "Remove",
              "TagKey": "DisplayNumber",
              "TagValue": "",
              "MatchKey": "",
              "MatchValue": "",
              "Radius": 1.0,
              "Center": "Volume"
            }
          ],
          "Conditions": [
            {
              "Type": "TagCondition",
              "Event": "TAG_ADDED",
              "Source": "Self",
              "TagKey": "Clearable",
              "TagValue": "1",
              "MatchKey": "",
              "MatchValue": "",
              "Radius": 1.0,
              "Center": "Volume"
            }
          ],
          "Enabled": true,
          "TargetTypes": [
            "Player"
          ],
          "Tags": {
            "ID": "Display2"
          },
          "KeepLoaded": false,
          "GroupLinkId": "ab62ddef-cc27-46fe-806f-08f0ac74c073",
          "PrefabIndex": 14
        }
      }
    },
    {
      "Components": {
        "Transform": {
          "Position": {
            "X": -0.5,
            "Y": 2.5,
            "Z": -1.5
          },
          "Rotation": {
            "Pitch": 0.0,
            "Yaw": 0.0,
            "Roll": 0.0
          }
        },
        "TriggerVolume": {
          "Shape": {
            "Type": "Box",
            "Min": {
              "X": -0.5,
              "Y": -0.5,
              "Z": -0.5
            },
            "Max": {
              "X": 0.5,
              "Y": 0.5,
              "Z": 0.5
            }
          },
          "Effects": [
            {
              "Type": "PlaceBlock",
              "Event": "TAG_ADDED",
              "Interval": 0.0,
              "Delay": 0.0,
              "BlockType": "Soil_Clay_Smooth_Black",
              "Position": {
                "X": 0.0,
                "Y": 0.0,
                "Z": 0.0
              },
              "Origin": "VolumeOrigin",
